Workbook

Sheet 개요
A1: Wellbian KOL KPI — 2026-09-28 실측
A2: KOL 라운드(노드 판매) 후보 선별용 · 수집: X·TG·YT 공개 페이지 직접 조회 · TwitterScore = twitterscore.io 공개값
A4: 탭 구성
A5: KOL 통합 | B5: KOL 1명 = 1행. 지역·링크·대표 채널 KPI·퍼포먼스·TwitterScore를 한 줄에 (KOL Asset 시트 형식)
A6: 글로벌 X / YT / TG | B6: 채널별 24시간 · 7일 · 30일 퍼포먼스 (게시 수 · 평균 조회 · ER · 평균 반응 · 도달률)
A7: 한국 TG / YT / X | B7: 동일 기준. 한국은 TG 중심 (TG에는 좋아요 수치가 없어 도달률 = 조회÷구독자로 반응을 봄)
A8: TwitterScore | B8: 56개 X 계정 영향력 점수 · 스마트 팔로워 · 30일 퍼포먼스 등급 대조
A9: KOL Rounds 선정 | B9: 선정 규칙 → 1차 / 예비 / 런칭 홍보용 / 보류, KOL별 선정 이유
A11: 퍼포먼스 등급 [제안 기준]
A12: 등급 | B12: X (게시물당 평균 반응) | C12: TG (30일 중앙 조회) | D12: YT 롱폼 (30일 중앙 조회)
A13: P1 | B13: 400+ | C13: 3,000+ | D13: 10,000+
A14: P2 | B14: 150–399 | C14: 1,500–2,999 | D14: 3,000–9,999
A15: P3 | B15: 50–149 | C15: 500–1,499 | D15: 1,000–2,999
A16: P4 | B16: 50 미만 | C16: 500 미만 | D16: 1,000 미만
A17: 비활동 | B17: 30일 3건 미만 | C17: 30일 3건 미만 | D17: 30일 롱폼 0개
A19: KPI 정의
A20: 평균 조회 | B20: 기간 내 본인 게시물 조회수 평균 (리포스트·고정글 제외)
A21: ER | B21: (좋아요 + 답글 + 리포스트) ÷ 조회 — X만 측정 가능
A22: 평균 반응 | B22: 게시물 1건이 만드는 반응 수 = 평균 조회 × ER
A23: 도달률 | B23: TG·YT: 30일 중앙 조회 ÷ 구독자 / X: 30일 평균 조회 ÷ 팔로워
A24: 추세 | B24: 7일 평균 조회 ÷ 30일 평균 조회 − 1 (+면 최근 상승)
A25: TwitterScore | B25: S 200+ · A 100–199 · B 40–99 · C 15–39 · D 15 미만. 스마트 팔로워 = 영향력 계정 팔로워 수
A27: 현황 (KOL 단위, 대표 채널 기준)
A28: 지역 | B28: P1 | C28: P2 | D28: P3 | E28: P4 | F28: 비활동·없음 | G28: 합계
A29: 한국 | B29: 3 | C29: 11 | D29: 21 | E29: 24 | F29: 22 | G29: 81
A30: 글로벌 | B30: 8 | C30: 12 | D30: 14 | E30: 11 | F30: 9 | G30: 54
A32: 주의
A33: ⚠️ 게시량이 많은 계정은 30일을 다 불러오지 못해 일부 기간만 집계 (각 탭 메모에 '○/○ 이후만 수집' 표기)
A34: ⚠️ 병합·이동 [추정]: CoinFluencer #6+#47 · 나백이 #19+#39 · X @coinboy717 → 코인소년 · @AlphaSchool77 → 알파스쿨
A35: ⚠️ 적합성(DePIN·노드·XRP 홍보 이력, 스캠 홍보 이력)은 미측정 — 접촉 전 확인
A36: ⚠️ 제안 직전 수치 재측정 필요 (8/25 원본 시트 팔로워는 TG+YT 합산값이 섞여 있어 이 시트는 실측값만 사용)

Sheet KOL 통합
A1: KOL 통합 — 135명 (한국 81 · 글로벌 54)
A2: ■ KOL 1명 = 1행. 대표 채널 = 퍼포먼스가 가장 높은 채널이며, 팔로워·게시·조회는 대표 채널의 9/28 실측값
A3: ■ 퍼포먼스 등급 [제안 기준] — X: 게시물당 평균 반응(평균 조회×ER) P1 400+ · P2 150+ · P3 50+ · P4 50 미만 / TG: 30일 중앙 조회 P1 3,000+ · P2 1,500+ · P3 500+ / YT 롱폼: 30일 중앙 조회 P1 10,000+ · P2 3,000+ · P3 1,000+ / 비활동: 30일 게시 X·TG 3건 미만, YT 롱폼 0개
A4: ■ 게시물당 조회: X = 30일 평균 조회, TG·YT = 30일 중앙 조회 · 도달률 = 게시물당 조회 ÷ 팔로워(구독자) · ER은 X 계정 기준
A5: ■ 재단·KOL 제안 전에는 해당 채널 수치를 다시 확인할 것
F7: 퍼포먼스 · 30일 (대표 채널) | L7: TwitterScore | O7: 링크
A8: 지역 | B8: 카테고리 | C8: 이름/핸들 | D8: 대표 채널 | E8: 활동 채널 | F8: 퍼포먼스 | G8: 팔로워/구독 | H8: 30일 게시 | I8: 게시물당 조회 | J8: ER (X) | K8: 도달률 | L8: Twitter Score | M8: TS 등급 | N8: 스마트 팔로워 | O8: X 링크 | P8: TG 링크 | Q8: YT 링크 | R8: 검증 | S8: 검증일 | T8: 비고 | U8: 출처 | V8: KOL ID | W8: 대표 채널 ID | X8: 계정 연결 | Y8: 측정일 | Z8: 후속 검토
A9: KR | C9: 코인하는 해달 | D9: Telegram | E9: TG | F9: P1 | G9: 30100 | H9: 133 | I9: 5000 | K9: 0.16611296 | P9: https://t.me/seaotterbtc | R9: ✅ 실측 | S9: 2026-09-28 | T9: 한국 1위 | U9: W1 검증 KOL (8/25 원본) → 9/28 재측정 | V9: WB-K001 | W9: WB-C099 | X9: 기존 목록 연결 | Y9: 46293 | Z9: 노드 구매·적합성·과거 판매 실적 미확인
A10: KR | C10: CoinFluencer | D10: Telegram | E10: X·TG·YT | F10: P1 | G10: 6630 | H10: 4 | I10: 3290 | K10: 0.49622926 | L10: 2 | M10: D | N10: 6 | O10: https://x.com/TheP2E_NFT | P10: https://t.me/hjwnews | Q10: https://www.youtube.com/@CoinFluencer | R10: ✅ 실측 | S10: 2026-09-28 | T10: 동일 브랜드 병합 [추정] · X 시트 100,000 → 실제 7,219 · 저빈도 (마지막 9/17) | U10: W1 검증 KOL (8/25 원본) → 9/28 재측정 | V10: WB-K002 | W10: WB-C098 | X10: 연결 확인 필요 | Y10: 46293 | Z10: 노드 구매·적합성·과거 판매 실적 미확인
A11: KR | C11: 취미생활방 | D11: Telegram | E11: TG | F11: P1 | G11: 49700 | H11: 431 | I11: 3010 | K11: 0.06056338 | P11: https://t.me/enjoymyhobby | R11: ✅ 실측 | S11: 2026-09-28 | T11: 하루 14건 → 고정 필요 | U11: W1 검증 KOL (8/25 원본) → 9/28 재측정 | V11: WB-K003 | W11: WB-C100 | X11: 기존 목록 연결 | Y11: 46293 | Z11: 노드 구매·적합성·과거 판매 실적 미확인
A12: KR | C12: 매실남 | D12: YouTube | E12: YT | F12: P2 | G12: 10200 | H12: 3 | I12: 6200 | K12: 0.60784314 | Q12: https://www.youtube.com/@pluman | R12: ✅ 실측 | S12: 2026-09-28 | U12: W1 검증 KOL (8/25 원본) → 9/28 재측정 | V12: WB-K004 | W12: WB-C165 | X12: 기존 목록 연결 | Y12: 46293 | Z12: 노드 구매·적합성·과거 판매 실적 미확인
A13: KR | C13: 코백남 | D13: YouTube | E13: TG·YT | F13: P2 | G13: 57900 | H13: 1 | I13: 4300 | K13: 0.074265976 | P13: https://t.me/cobacknamannounce | Q13: https://www.youtube.com/@cobacknam | R13: ✅ 실측 | S13: 2026-09-28 | T13: 시트 팔로워는 TG+YT 합산 · TG 채널 병행 | U13: W1 검증 KOL (8/25 원본) → 9/28 재측정 | V13: WB-K005 | W13: WB-C166 | X13: 기존 목록 연결 | Y13: 46293 | Z13: 노드 구매·적합성·과거 판매 실적 미확인
A14: KR | C14: 졸업준비위원회 | D14: Telegram | E14: TG | F14: P2 | G14: 23000 | H14: 157 | I14: 2830 | K14: 0.12304348 | P14: https://t.me/officialunivercityofcrypto | R14: ✅ 실측 | S14: 2026-09-28 | U14: W1 검증 KOL (8/25 원본) → 9/28 재측정 | V14: WB-K006 | W14: WB-C105 | X14: 기존 목록 연결 | Y14: 46293 | Z14: 노드 구매·적합성·과거 판매 실적 미확인
A15: KR | C15: Crypto Judy | D15: Telegram | E15: TG | F15: P2 | G15: 17400 | H15: 839 | I15: 2210 | K15: 0.12701149 | P15: https://t.me/lovejudylee | R15: ✅ 실측 | S15: 2026-09-28 | T15: 하루 28건+ → 공지 묻힘 위험 · 30일 일부만 수집 | U15: W1 검증 KOL (8/25 원본) → 9/28 재측정 | V15: WB-K007 | W15: WB-C104 | X15: 기존 목록 연결 | Y15: 46293 | Z15: 노드 구매·적합성·과거 판매 실적 미확인
A16: KR | C16: 라오니 | D16: Telegram | E16: TG | F16: P2 | G16: 14900 | H16: 329 | I16: 2200 | K16: 0.14765101 | P16: https://t.me/Raoni1 | R16: ✅ 실측 | S16: 2026-09-28 | U16: W1 검증 KOL (8/25 원본) → 9/28 재측정 | V16: WB-K008 | W16: WB-C103 | X16: 기존 목록 연결 | Y16: 46293 | Z16: 노드 구매·적합성·과거 판매 실적 미확인
A17: KR | C17: 신기돈 | D17: Telegram | E17: TG | F17: P2 | G17: 22900 | H17: 137 | I17: 1840 | K17: 0.080349345 | P17: https://t.me/tlsrltnf | R17: ✅ 실측 | S17: 2026-09-28 | U17: W1 검증 KOL (8/25 원본) → 9/28 재측정 | V17: WB-K009 | W17: WB-C107 | X17: 기존 목록 연결 | Y17: 46293 | Z17: 노드 구매·적합성·과거 판매 실적 미확인
A18: KR | C18: 크립토마카세 | D18: Telegram | E18: TG | F18: P2 | G18: 11000 | H18: 25 | I18: 1830 | K18: 0.16636364 | P18: https://t.me/cryptomacase | R18: ✅ 실측 | S18: 2026-09-28 | T18: 저빈도 · 고효율 | U18: W1 검증 KOL (8/25 원본) → 9/28 재측정 | V18: WB-K010 | W18: WB-C102 | X18: 기존 목록 연결 | Y18: 46293 | Z18: 노드 구매·적합성·과거 판매 실적 미확인
A19: KR | C19: jobless | D19: Telegram | E19: TG | F19: P2 | G19: 6050 | H19: 6 | I19: 1750 | K19: 0.2892562 | P19: https://t.me/Jobless_investor | R19: ✅ 실측 | S19: 2026-09-28 | T19: 마지막 9/3 | U19: W1 검증 KOL (8/25 원본) → 9/28 재측정 | V19: WB-K011 | W19: WB-C101 | X19: 기존 목록 연결 | Y19: 46293 | Z19: 노드 구매·적합성·과거 판매 실적 미확인
A20: KR | C20: 마샬 | D20: Telegram | E20: TG | F20: P2 | G20: 21700 | H20: 154 | I20: 1730 | K20: 0.079723502 | P20: https://t.me/marshallog | R20: ✅ 실측 | S20: 2026-09-28 | U20: W1 검증 KOL (8/25 원본) → 9/28 재측정 | V20: WB-K012 | W20: WB-C108 | X20: 기존 목록 연결 | Y20: 46293 | Z20: 노드 구매·적합성·과거 판매 실적 미확인
A21: KR | C21: 잼민123 | D21: Telegram | E21: TG·YT | F21: P2 | G21: 26200 | H21: 430 | I21: 1690 | K21: 0.064503817 | P21: https://t.me/mujammin123 | Q21: https://www.youtube.com/@jammin2 | R21: ✅ 실측 | S21: 2026-09-28 | U21: W1 검증 KOL (8/25 원본) → 9/28 재측정 | V21: WB-K013 | W21: WB-C109 | X21: 기존 목록 연결 | Y21: 46293 | Z21: 노드 구매·적합성·과거 판매 실적 미확인
A22: KR | C22: 킬베로스 | D22: Telegram | E22: TG | F22: P2 | G22: 15100 | H22: 38 | I22: 1650 | K22: 0.10927152 | P22: https://t.me/killberosDAO | R22: ✅ 실측 | S22: 2026-09-28 | T22: 8/25 대비 하락 | U22: W1 검증 KOL (8/25 원본) → 9/28 재측정 | V22: WB-K014 | W22: WB-C106 | X22: 기존 목록 연결 | Y22: 46293 | Z22: 노드 구매·적합성·과거 판매 실적 미확인
A23: KR | C23: 나백이 | D23: YouTube | E23: X·TG·YT | F23: P3 | G23: 16700 | H23: 1 | I23: 2900 | J23: 0.0054 | K23: 0.17365269 | L23: 17 | M23: C | N23: 164 | O23: https://x.com/Naback222 | P23: https://t.me/ysytop2 | Q23: https://www.youtube.com/@naback222 | R23: ✅ 실측 | S23: 2026-09-28 | T23: 동일인 병합 [추정] | U23: W1 검증 KOL (8/25 원본) → 9/28 재측정 | V23: WB-K015 | W23: WB-C168 | X23: 연결 확인 필요 | Y23: 46293 | Z23: 노드 구매·적합성·과거 판매 실적 미확인
A24: KR | C24: 코인소년 | D24: YouTube | E24: X·TG·YT | F24: P3 | G24: 53200 | H24: 6 | I24: 2200 | J24: 0.0172 | K24: 0.041353383 | L24: 11 | M24: D | N24: 82 | O24: https://x.com/coinboy717 | P24: https://t.me/coinboys | Q24: https://www.youtube.com/@coinboys | R24: ✅ 실측 | S24: 2026-09-28 | T24: X @coinboy717 표시명 '코인소년' → 시트(#48)에서 이동 [추정] · TG 채널 병행 | U24: W1 검증 KOL (8/25 원본) → 9/28 재측정 | V24: WB-K016 | W24: WB-C169 | X24: 연결 확인 필요 | Y24: 46293 | Z24: 노드 구매·적합성·과거 판매 실적 미확인
A25: KR | C25: 요블이네 | D25: Telegram | E25: TG | F25: P3 | G25: 22700 | H25: 185 | I25: 1480 | K25: 0.065198238 | P25: https://t.me/yobeullyANN | R25: ✅ 실측 | S25: 2026-09-28 | U25: W1 검증 KOL (8/25 원본) → 9/28 재측정 | V25: WB-K017 | W25: WB-C126 | X25: 기존 목록 연결 | Y25: 46293 | Z25: 노드 구매·적합성·과거 판매 실적 미확인
A26: KR | C26: 알파스쿨 | D26: Telegram | E26: X·TG | F26: P3 | G26: 10800 | H26: 101 | I26: 1300 | J26: 0.0292 | K26: 0.12037037 | L26: 4 | M26: D | N26: 51 | O26: https://x.com/AlphaSchool77 | P26: https://t.me/AlphaSchool77 | R26: ✅ 실측 | S26: 2026-09-28 | T26: X @AlphaSchool77 → 시트(#51)에서 이동 [추정] · X는 WL 기브어웨이 위주 | U26: W1 검증 KOL (8/25 원본) → 9/28 재측정 | V26: WB-K018 | W26: WB-C114 | X26: 연결 확인 필요 | Y26: 46293 | Z26: 노드 구매·적합성·과거 판매 실적 미확인
A27: KR | C27: T.A Crypto | D27: YouTube | E27: TG·YT | F27: P3 | G27: 7410 | H27: 1 | I27: 1200 | K27: 0.16194332 | P27: https://t.me/yul_papa | Q27: https://www.youtube.com/@TA_crypto | R27: ✅ 실측 | S27: 2026-09-28 | T27: TG 채널 병행 | U27: W1 검증 KOL (8/25 원본) → 9/28 재측정 | V27: WB-K019 | W27: WB-C170 | X27: 기존 목록 연결 | Y27: 46293 | Z27: 노드 구매·적합성·과거 판매 실적 미확인
A28: KR | C28: BMT | D28: Telegram | E28: TG | F28: P3 | G28: 13700 | H28: 84 | I28: 1200 | K28: 0.087591241 | P28: https://t.me/BMTube | R28: ✅ 실측 | S28: 2026-09-28 | U28: W1 검증 KOL (8/25 원본) → 9/28 재측정 | V28: WB-K020 | W28: WB-C120 | X28: 기존 목록 연결 | Y28: 46293 | Z28: 노드 구매·적합성·과거 판매 실적 미확인
A29: KR | C29: 개인적인 DYOR | D29: Telegram | E29: TG | F29: P3 | G29: 9730 | H29: 67 | I29: 976 | K29: 0.10030832 | P29: https://t.me/LEEHEESANGDYOR | R29: ✅ 실측 | S29: 2026-09-28 | U29: W1 검증 KOL (8/25 원본) → 9/28 재측정 | V29: WB-K021 | W29: WB-C119 | X29: 기존 목록 연결 | Y29: 46293 | Z29: 노드 구매·적합성·과거 판매 실적 미확인
A30: KR | C30: 바나나우유 일기장 | D30: Telegram | E30: TG | F30: P3 | G30: 8760 | H30: 10 | I30: 892 | K30: 0.10182648 | P30: https://t.me/Bananamilkrich | R30: ✅ 실측 | S30: 2026-09-28 | U30: W1 검증 KOL (8/25 원본) → 9/28 재측정 | V30: WB-K022 | W30: WB-C117 | X30: 기존 목록 연결 | Y30: 46293 | Z30: 노드 구매·적합성·과거 판매 실적 미확인
A31: KR | C31: Trader Hyun | D31: Telegram | E31: TG | F31: P3 | G31: 6530 | H31: 14 | I31: 880 | K31: 0.13476263 | P31: https://t.me/TraderHyun | R31: ✅ 실측 | S31: 2026-09-28 | U31: W1 검증 KOL (8/25 원본) → 9/28 재측정 | V31: WB-K023 | W31: WB-C112 | X31: 기존 목록 연결 | Y31: 46293 | Z31: 노드 구매·적합성·과거 판매 실적 미확인
A32: KR | C32: 에어드랍코리아 | D32: Telegram | E32: TG | F32: P3 | G32: 21900 | H32: 131 | I32: 844 | K32: 0.038538813 | P32: https://t.me/airdrop_kor | R32: ✅ 실측 | S32: 2026-09-28 | T32: 에어드랍 키워드 | U32: W1 검증 KOL (8/25 원본) → 9/28 재측정 | V32: WB-K024 | W32: WB-C130 | X32: 기존 목록 연결 | Y32: 46293 | Z32: 노드 구매·적합성·과거 판매 실적 미확인
A33: KR | C33: BQ 비큐 | D33: Telegram | E33: TG | F33: P3 | G33: 9600 | H33: 98 | I33: 821 | K33: 0.085520833 | P33: https://t.me/BQTelegram | R33: ✅ 실측 | S33: 2026-09-28 | U33: W1 검증 KOL (8/25 원본) → 9/28 재측정 | V33: WB-K025 | W33: WB-C121 | X33: 기존 목록 연결 | Y33: 46293 | Z33: 노드 구매·적합성·과거 판매 실적 미확인
A34: KR | C34: 젠티 | D34: Telegram | E34: TG | F34: P3 | G34: 14400 | H34: 94 | I34: 772 | K34: 0.053611111 | P34: https://t.me/Jenti_DeFi | R34: ✅ 실측 | S34: 2026-09-28 | U34: W1 검증 KOL (8/25 원본) → 9/28 재측정 | V34: WB-K026 | W34: WB-C128 | X34: 기존 목록 연결 | Y34: 46293 | Z34: 노드 구매·적합성·과거 판매 실적 미확인
A35: KR | C35: 크립토폴유 | D35: Telegram | E35: TG | F35: P3 | G35: 7620 | H35: 35 | I35: 766 | K35: 0.10052493 | P35: https://t.me/cryptoforu12 | R35: ✅ 실측 | S35: 2026-09-28 | U35: W1 검증 KOL (8/25 원본) → 9/28 재측정 | V35: WB-K027 | W35: WB-C118 | X35: 기존 목록 연결 | Y35: 46293 | Z35: 노드 구매·적합성·과거 판매 실적 미확인
A36: KR | C36: Road To Rome | D36: Telegram | E36: TG | F36: P3 | G36: 4840 | H36: 6 | I36: 718 | K36: 0.14834711 | P36: https://t.me/HeadingtoRome | R36: ✅ 실측 | S36: 2026-09-28 | U36: W1 검증 KOL (8/25 원본) → 9/28 재측정 | V36: WB-K028 | W36: WB-C111 | X36: 기존 목록 연결 | Y36: 46293 | Z36: 노드 구매·적합성·과거 판매 실적 미확인
A37: KR | C37: A라는 사람 | D37: Telegram | E37: TG | F37: P3 | G37: 3920 | H37: 18 | I37: 707 | K37: 0.18035714 | P37: https://t.me/aispersons | R37: ✅ 실측 | S37: 2026-09-28 | T37: 8/25 대비 하락 | U37: W1 검증 KOL (8/25 원본) → 9/28 재측정 | V37: WB-K029 | W37: WB-C110 | X37: 기존 목록 연결 | Y37: 46293 | Z37: 노드 구매·적합성·과거 판매 실적 미확인
A38: KR | C38: 꿀찾는 양말 | D38: Telegram | E38: TG | F38: P3 | G38: 11400 | H38: 460 | I38: 628 | K38: 0.055087719 | P38: https://t.me/Honeyofwhitesocks_2 | R38: ✅ 실측 | S38: 2026-09-28 | U38: W1 검증 KOL (8/25 원본) → 9/28 재측정 | V38: WB-K030 | W38: WB-C127 | X38: 기존 목록 연결 | Y38: 46293 | Z38: 노드 구매·적합성·과거 판매 실적 미확인
A39: KR | C39: 큐브 | D39: Telegram | E39: TG | F39: P3 | G39: 9320 | H39: 38 | I39: 624 | K39: 0.06695279 | P39: https://t.me/cubestudy1557 | R39: ✅ 실측 | S39: 2026-09-28 | U39: W1 검증 KOL (8/25 원본) → 9/28 재측정 | V39: WB-K031 | W39: WB-C124 | X39: 기존 목록 연결 | Y39: 46293 | Z39: 노드 구매·적합성·과거 판매 실적 미확인
A40: KR | C40: 코인맵핵 | D40: Telegram | E40: TG | F40: P3 | G40: 16700 | H40: 76 | I40: 617 | K40: 0.036946108 | P40: https://t.me/centurywhale | R40: ✅ 실측 | S40: 2026-09-28 | U40: W1 검증 KOL (8/25 원본) → 9/28 재측정 | V40: WB-K032 | W40: WB-C131 | X40: 기존 목록 연결 | Y40: 46293 | Z40: 노드 구매·적합성·과거 판매 실적 미확인
A41: KR | C41: 코인위키 | D41: Telegram | E41: TG | F41: P3 | G41: 5910 | H41: 82 | I41: 615 | K41: 0.10406091 | P41: https://t.me/CoinWiki_MMWW | R41: ✅ 실측 | S41: 2026-09-28 | U41: W1 검증 KOL (8/25 원본) → 9/28 재측정 | V41: WB-K033 | W41: WB-C115 | X41: 기존 목록 연결 | Y41: 46293 | Z41: 노드 구매·적합성·과거 판매 실적 미확인
...

Sheet 글로벌 X
A1: 글로벌 X — 43개 계정
A2: ■ 정렬: 퍼포먼스 → 30일 평균 반응 높은 순 · 본인 글만 집계 (리포스트·고정 제외) · 수집 2026-09-28
A3: ■ 퍼포먼스 등급 [제안 기준] — X: 게시물당 평균 반응(평균 조회×ER) P1 400+ · P2 150+ · P3 50+ · P4 50 미만 · 비활동 = 30일 3건 미만
A4: ■ ⚠️ 게시량 과다 계정은 일부 기간만 수집 (메모 참고) · @haloETH ER은 답글 비중 과다로 참고만
D6: 영향력 | H6: 24시간 | L6: 7일 | P6: 30일
A7: 순위 | B7: KOL | C7: 퍼포먼스 | D7: Twitter Score | E7: TS 등급 | F7: 스마트 팔로워 | G7: 팔로워 | H7: 게시 | I7: 평균 조회 | J7: 평균 반응 | K7: ER | L7: 게시 | M7: 평균 조회 | N7: 평균 반응 | O7: ER | P7: 게시 | Q7: 평균 조회 | R7: 평균 반응 | S7: ER | T7: 도달률 (조회÷팔로워) | U7: 추세 (7d vs 30d) | V7: 메모 | W7: 링크 | X7: 채널 ID | Y7: KOL ID | Z7: 측정 상태
A8: 1 | B8: @midrizzy1 | C8: P1 | D8: 1 | E8: D | F8: 6 | G8: 89700 | L8: 2 | M8: 98126 | N8: 2198.0224 | O8: 0.0224 | P8: 11 | Q8: 62411 | R8: 1747.508 | S8: 0.028 | T8: 0.6957748 | U8: 0.57225489 | V8: 포렉스·라이프스타일 비중 높음 | W8: https://x.com/midrizzy1 | X8: WB-C001 | Y8: WB-K086 | Z8: {=_xlfn.XLOOKUP(X8,'측정 관리'!$A$5:$A$204,'측정 관리'!$K$5:$K$204,"",0)} -> 기간 확인 필요
A9: 2 | B9: @IncomeSharks | C9: P1 | D9: 235 | E9: S | F9: 2206 | G9: 742429 | H9: 1 | I9: 68228 | J9: 743.6852 | K9: 0.0109 | L9: 9 | M9: 85897 | N9: 764.4833 | O9: 0.0089 | P9: 40 | Q9: 89477 | R9: 697.9206 | S9: 0.0078 | T9: 0.12051927 | U9: -0.040010282 | W9: https://x.com/IncomeSharks | X9: WB-C002 | Y9: WB-K082 | Z9: {=_xlfn.XLOOKUP(X9,'측정 관리'!$A$5:$A$204,'측정 관리'!$K$5:$K$204,"",0)}
A10: 3 | B10: @CryptoPoseidonn | C10: P1 | D10: 128 | E10: A | F10: 990 | G10: 175000 | L10: 3 | M10: 66587 | N10: 685.8461 | O10: 0.0103 | P10: 11 | Q10: 74045 | R10: 659.0005 | S10: 0.0089 | T10: 0.42311429 | U10: -0.10072253 | V10: 도달률 42% · 효율 최상 | W10: https://x.com/CryptoPoseidonn | X10: WB-C003 | Y10: WB-K085 | Z10: {=_xlfn.XLOOKUP(X10,'측정 관리'!$A$5:$A$204,'측정 관리'!$K$5:$K$204,"",0)}
A11: 4 | B11: @eliz883 | C11: P1 | D11: 133 | E11: A | F11: 1208 | G11: 610000 | H11: 14 | I11: 61808 | J11: 414.1136 | K11: 0.0067 | L11: 90 | M11: 77406 | N11: 642.4698 | O11: 0.0083 | P11: 304 | Q11: 85107 | R11: 561.7062 | S11: 0.0066 | T11: 0.13951967 | U11: -0.090486094 | W11: https://x.com/eliz883 | X11: WB-C004 | Y11: WB-K084 | Z11: {=_xlfn.XLOOKUP(X11,'측정 관리'!$A$5:$A$204,'측정 관리'!$K$5:$K$204,"",0)}
A12: 5 | B12: @Trader_XO | C12: P1 | D12: 270 | E12: S | F12: 2422 | G12: 550420 | H12: 3 | I12: 32786 | J12: 98.358 | K12: 0.003 | L12: 27 | M12: 86878 | N12: 408.3266 | O12: 0.0047 | P12: 59 | Q12: 85386 | R12: 409.8528 | S12: 0.0048 | T12: 0.15512881 | U12: 0.017473591 | W12: https://x.com/Trader_XO | X12: WB-C005 | Y12: WB-K083 | Z12: {=_xlfn.XLOOKUP(X12,'측정 관리'!$A$5:$A$204,'측정 관리'!$K$5:$K$204,"",0)}
A13: 6 | B13: @DeRonin_ | C13: P2 | D13: 153 | E13: A | F13: 1234 | G13: 118197 | H13: 1 | I13: 41344 | J13: 628.4288 | K13: 0.0152 | L13: 7 | M13: 22230 | N13: 342.342 | O13: 0.0154 | P13: 48 | Q13: 39946 | R13: 383.4816 | S13: 0.0096 | T13: 0.3379612 | U13: -0.44349872 | V13: 가성비 후보 | W13: https://x.com/DeRonin_ | X13: WB-C006 | Y13: WB-K091 | Z13: {=_xlfn.XLOOKUP(X13,'측정 관리'!$A$5:$A$204,'측정 관리'!$K$5:$K$204,"",0)}
A14: 7 | B14: @rektcapital | C14: P2 | D14: 193 | E14: A | F14: 1860 | G14: 563000 | L14: 25 | M14: 52314 | N14: 360.9666 | O14: 0.0069 | P14: 81 | Q14: 65242 | R14: 345.7826 | S14: 0.0053 | T14: 0.11588277 | U14: -0.19815456 | W14: https://x.com/rektcapital | X14: WB-C007 | Y14: WB-K090 | Z14: {=_xlfn.XLOOKUP(X14,'측정 관리'!$A$5:$A$204,'측정 관리'!$K$5:$K$204,"",0)} -> 기간 확인 필요
A15: 8 | B15: @nobrainflip | C15: P2 | D15: 163 | E15: A | F15: 1645 | G15: 543000 | H15: 4 | I15: 139397 | J15: 376.3719 | K15: 0.0027 | L15: 52 | M15: 80919 | N15: 291.3084 | O15: 0.0036 | P15: 71 | Q15: 80343 | R15: 329.4063 | S15: 0.0041 | T15: 0.14796133 | U15: 0.0071692618 | W15: https://x.com/nobrainflip | X15: WB-C008 | Y15: WB-K100 | Z15: {=_xlfn.XLOOKUP(X15,'측정 관리'!$A$5:$A$204,'측정 관리'!$K$5:$K$204,"",0)}
A16: 9 | B16: @inmortalcrypto | C16: P2 | D16: 145 | E16: A | F16: 1257 | G16: 232451 | L16: 14 | M16: 31005 | N16: 384.462 | O16: 0.0124 | P16: 42 | Q16: 25898 | R16: 292.6474 | S16: 0.0113 | T16: 0.11141273 | U16: 0.19719669 | W16: https://x.com/inmortalcrypto | X16: WB-C009 | Y16: WB-K095 | Z16: {=_xlfn.XLOOKUP(X16,'측정 관리'!$A$5:$A$204,'측정 관리'!$K$5:$K$204,"",0)}
A17: 10 | B17: @follis_ | C17: P2 | D17: 121 | E17: A | F17: 876 | G17: 128000 | H17: 5 | I17: 16513 | J17: 232.8333 | K17: 0.0141 | L17: 33 | M17: 18918 | N17: 304.5798 | O17: 0.0161 | P17: 145 | Q17: 26419 | R17: 287.9671 | S17: 0.0109 | T17: 0.20639844 | U17: -0.28392445 | W17: https://x.com/follis_ | X17: WB-C010 | Y17: WB-K094 | Z17: {=_xlfn.XLOOKUP(X17,'측정 관리'!$A$5:$A$204,'측정 관리'!$K$5:$K$204,"",0)}
A18: 11 | B18: @ColdBloodShill | C18: P2 | D18: 423 | E18: S | F18: 3185 | G18: 352483 | H18: 2 | I18: 17567 | J18: 149.3195 | K18: 0.0085 | L18: 19 | M18: 27263 | N18: 245.367 | O18: 0.009 | P18: 146 | Q18: 38127 | R18: 259.2636 | S18: 0.0068 | T18: 0.10816692 | U18: -0.28494243 | W18: https://x.com/ColdBloodShill | X18: WB-C011 | Y18: WB-K092 | Z18: {=_xlfn.XLOOKUP(X18,'측정 관리'!$A$5:$A$204,'측정 관리'!$K$5:$K$204,"",0)}
A19: 12 | B19: @FefeDemeny | C19: P2 | D19: 59 | E19: B | F19: 447 | G19: 66900 | H19: 2 | I19: 12407 | J19: 116.6258 | K19: 0.0094 | L19: 17 | M19: 17577 | N19: 186.3162 | O19: 0.0106 | P19: 45 | Q19: 19233 | R19: 225.0261 | S19: 0.0117 | T19: 0.28748879 | U19: -0.086102012 | W19: https://x.com/FefeDemeny | X19: WB-C012 | Y19: WB-K088 | Z19: {=_xlfn.XLOOKUP(X19,'측정 관리'!$A$5:$A$204,'측정 관리'!$K$5:$K$204,"",0)}
A20: 13 | B20: @EricCryptoman | C20: P2 | D20: 227 | E20: S | F20: 1898 | G20: 272253 | H20: 2 | I20: 17946 | J20: 224.325 | K20: 0.0125 | L20: 30 | M20: 20823 | N20: 191.5716 | O20: 0.0092 | P20: 181 | Q20: 23777 | R20: 209.2376 | S20: 0.0088 | T20: 0.087334208 | U20: -0.12423771 | W20: https://x.com/EricCryptoman | X20: WB-C013 | Y20: WB-K101 | Z20: {=_xlfn.XLOOKUP(X20,'측정 관리'!$A$5:$A$204,'측정 관리'!$K$5:$K$204,"",0)}
A21: 14 | B21: @haloETH | C21: P2 | D21: 47 | E21: B | F21: 444 | G21: 58015 | L21: 2 | M21: 2986 | N21: 318.9048 | O21: 0.1068 | P21: 16 | Q21: 5438 | R21: 201.7498 | S21: 0.0371 | T21: 0.093734379 | U21: -0.45090107 | V21: 답글 비중 과다 · 참여 품앗이 의심 | W21: https://x.com/haloETH | X21: WB-C014 | Y21: WB-K098 | Z21: {=_xlfn.XLOOKUP(X21,'측정 관리'!$A$5:$A$204,'측정 관리'!$K$5:$K$204,"",0)}
A22: 15 | B22: @MuroCrypto | C22: P2 | D22: 143 | E22: A | F22: 1249 | G22: 403000 | L22: 32 | M22: 39978 | N22: 187.8966 | O22: 0.0047 | P22: 147 | Q22: 35672 | R22: 171.2256 | S22: 0.0048 | T22: 0.088516129 | U22: 0.12071092 | W22: https://x.com/MuroCrypto | X22: WB-C015 | Y22: WB-K093 | Z22: {=_xlfn.XLOOKUP(X22,'측정 관리'!$A$5:$A$204,'측정 관리'!$K$5:$K$204,"",0)}
A23: 16 | B23: @DaanCrypto | C23: P2 | D23: 192 | E23: A | F23: 1601 | G23: 415069 | P23: 7 | Q23: 20832 | R23: 170.8224 | S23: 0.0082 | T23: 0.050189246 | V23: 8/30 이후 게시 없음 | W23: https://x.com/DaanCrypto | X23: WB-C016 | Y23: WB-K096 | Z23: {=_xlfn.XLOOKUP(X23,'측정 관리'!$A$5:$A$204,'측정 관리'!$K$5:$K$204,"",0)}
A24: 17 | B24: @AltcoinSherpa | C24: P3 | D24: 280 | E24: S | F24: 2014 | G24: 263424 | H24: 6 | I24: 13439 | J24: 114.2315 | K24: 0.0085 | L24: 98 | M24: 16398 | N24: 162.3402 | O24: 0.0099 | P24: 530 | Q24: 14357 | R24: 119.1631 | S24: 0.0083 | T24: 0.054501488 | U24: 0.14216062 | V24: 30일 530건 → 스폰서 글 묻힘 위험 | W24: https://x.com/AltcoinSherpa | X24: WB-C017 | Y24: WB-K104 | Z24: {=_xlfn.XLOOKUP(X24,'측정 관리'!$A$5:$A$204,'측정 관리'!$K$5:$K$204,"",0)}
A25: 18 | B25: @DeFiOracle_ | C25: P3 | D25: 46 | E25: B | F25: 413 | G25: 18700 | L25: 4 | M25: 8172 | N25: 79.2684 | O25: 0.0097 | P25: 18 | Q25: 7805 | R25: 115.514 | S25: 0.0148 | T25: 0.41737968 | U25: 0.04702114 | W25: https://x.com/DeFiOracle_ | X25: WB-C018 | Y25: WB-K106 | Z25: {=_xlfn.XLOOKUP(X25,'측정 관리'!$A$5:$A$204,'측정 관리'!$K$5:$K$204,"",0)}
A26: 19 | B26: @KoroushAK | C26: P3 | D26: 189 | E26: A | F26: 1556 | G26: 377469 | H26: 2 | I26: 12650 | J26: 65.78 | K26: 0.0052 | L26: 16 | M26: 19177 | N26: 109.3089 | O26: 0.0057 | P26: 63 | Q26: 19273 | R26: 96.365 | S26: 0.005 | T26: 0.051058498 | U26: -0.0049810616 | W26: https://x.com/KoroushAK | X26: WB-C019 | Y26: WB-K109 | Z26: {=_xlfn.XLOOKUP(X26,'측정 관리'!$A$5:$A$204,'측정 관리'!$K$5:$K$204,"",0)}
A27: 20 | B27: @PhilakoneCrypto | C27: P3 | D27: 52 | E27: B | F27: 503 | G27: 185000 | H27: 7 | I27: 17926 | J27: 75.2892 | K27: 0.0042 | L27: 44 | M27: 18320 | N27: 119.08 | O27: 0.0065 | P27: 157 | Q27: 15729 | R27: 91.2282 | S27: 0.0058 | T27: 0.085021622 | U27: 0.16472757 | W27: https://x.com/PhilakoneCrypto | X27: WB-C020 | Y27: WB-K099 | Z27: {=_xlfn.XLOOKUP(X27,'측정 관리'!$A$5:$A$204,'측정 관리'!$K$5:$K$204,"",0)}
A28: 21 | B28: @0xklarck | C28: P3 | D28: 12 | E28: D | F28: 118 | G28: 95400 | H28: 2 | I28: 8659 | J28: 33.7701 | K28: 0.0039 | L28: 18 | M28: 37359 | N28: 85.9257 | O28: 0.0023 | P28: 57 | Q28: 28303 | R28: 87.7393 | S28: 0.0031 | T28: 0.29667715 | U28: 0.31996608 | V28: 30일은 9/4 이후만 수집 | W28: https://x.com/0xklarck | X28: WB-C021 | Y28: WB-K102 | Z28: {=_xlfn.XLOOKUP(X28,'측정 관리'!$A$5:$A$204,'측정 관리'!$K$5:$K$204,"",0)}
A29: 22 | B29: @w1nklerr | C29: P3 | D29: 8 | E29: D | F29: 79 | G29: 61000 | H29: 1 | I29: 27940 | J29: 226.314 | K29: 0.0081 | L29: 12 | M29: 7772 | N29: 48.1864 | O29: 0.0062 | P29: 39 | Q29: 12384 | R29: 84.2112 | S29: 0.0068 | T29: 0.20301639 | U29: -0.37241602 | V29: 30일은 9/11 이후만 수집 · 유료 파트너십 게시 있음 | W29: https://x.com/w1nklerr | X29: WB-C022 | Y29: WB-K115 | Z29: {=_xlfn.XLOOKUP(X29,'측정 관리'!$A$5:$A$204,'측정 관리'!$K$5:$K$204,"",0)}
A30: 23 | B30: @evancrypt | C30: P3 | D30: 46 | E30: B | F30: 436 | G30: 30300 | H30: 1 | I30: 373 | J30: 7.0124 | K30: 0.0188 | L30: 3 | M30: 5652 | N30: 54.2592 | O30: 0.0096 | P30: 31 | Q30: 5881 | R30: 79.3935 | S30: 0.0135 | T30: 0.19409241 | U30: -0.038938956 | W30: https://x.com/evancrypt | X30: WB-C023 | Y30: WB-K108 | Z30: {=_xlfn.XLOOKUP(X30,'측정 관리'!$A$5:$A$204,'측정 관리'!$K$5:$K$204,"",0)}
A31: 24 | B31: @WhaleNoName | C31: P3 | D31: 20 | E31: C | F31: 175 | G31: 50800 | H31: 2 | I31: 5424 | J31: 46.6464 | K31: 0.0086 | L31: 36 | M31: 22663 | N31: 77.0542 | O31: 0.0034 | P31: 36 | Q31: 22663 | R31: 77.0542 | S31: 0.0034 | T31: 0.44612205 | U31: 0 | V31: 게시량 과다 · 30일은 9/21 이후만 수집 | W31: https://x.com/WhaleNoName | X31: WB-C024 | Y31: WB-K103 | Z31: {=_xlfn.XLOOKUP(X31,'측정 관리'!$A$5:$A$204,'측정 관리'!$K$5:$K$204,"",0)}
A32: 25 | B32: @spacexbt | C32: P3 | D32: 91 | E32: B | F32: 547 | G32: 18500 | H32: 1 | I32: 1722 | J32: 9.9876 | K32: 0.0058 | L32: 13 | M32: 2642 | N32: 15.0594 | O32: 0.0057 | P32: 31 | Q32: 10491 | R32: 65.0442 | S32: 0.0062 | T32: 0.56708108 | U32: -0.74816509 | W32: https://x.com/spacexbt | X32: WB-C025 | Y32: WB-K105 | Z32: {=_xlfn.XLOOKUP(X32,'측정 관리'!$A$5:$A$204,'측정 관리'!$K$5:$K$204,"",0)}
A33: 26 | B33: @0xjayn3 | C33: P3 | D33: 26 | E33: C | F33: 193 | G33: 32500 | H33: 7 | I33: 5099 | J33: 56.089 | K33: 0.011 | L33: 56 | M33: 5937 | N33: 58.1826 | O33: 0.0098 | P33: 56 | Q33: 5937 | R33: 58.1826 | S33: 0.0098 | T33: 0.18267692 | U33: 0 | V33: 게시량 과다 · 30일은 9/22 이후만 수집 | W33: https://x.com/0xjayn3 | X33: WB-C026 | Y33: WB-K107 | Z33: {=_xlfn.XLOOKUP(X33,'측정 관리'!$A$5:$A$204,'측정 관리'!$K$5:$K$204,"",0)}
A34: 27 | B34: @ChadCaff | C34: P4 | D34: 133 | E34: A | F34: 1138 | G34: 132000 | L34: 6 | M34: 6670 | N34: 46.023 | O34: 0.0069 | P34: 25 | Q34: 6494 | R34: 42.211 | S34: 0.0065 | T34: 0.04919697 | U34: 0.02710194 | V34: 점수 대비 약함 | W34: https://x.com/ChadCaff | X34: WB-C027 | Y34: WB-K116 | Z34: {=_xlfn.XLOOKUP(X34,'측정 관리'!$A$5:$A$204,'측정 관리'!$K$5:$K$204,"",0)}
A35: 28 | B35: @0xFrogify | C35: P4 | D35: 5 | E35: D | F35: 59 | G35: 45200 | H35: 1 | I35: 5837 | J35: 35.022 | K35: 0.006 | L35: 8 | M35: 6773 | N35: 38.6061 | O35: 0.0057 | P35: 34 | Q35: 9013 | R35: 27.9403 | S35: 0.0031 | T35: 0.19940265 | U35: -0.2485299 | W35: https://x.com/0xFrogify | X35: WB-C028 | Y35: WB-K125 | Z35: {=_xlfn.XLOOKUP(X35,'측정 관리'!$A$5:$A$204,'측정 관리'!$K$5:$K$204,"",0)}
A36: 29 | B36: @0xchromium | C36: P4 | D36: 24 | E36: C | F36: 201 | G36: 22800 | H36: 1 | I36: 1687 | J36: 40.9941 | K36: 0.0243 | L36: 13 | M36: 1897 | N36: 25.6095 | O36: 0.0135 | P36: 16 | Q36: 2009 | R36: 27.1215 | S36: 0.0135 | T36: 0.088114035 | U36: -0.055749129 | V36: 30일은 9/19 이후만 수집 | W36: https://x.com/0xchromium | X36: WB-C029 | Y36: WB-K120 | Z36: {=_xlfn.XLOOKUP(X36,'측정 관리'!$A$5:$A$204,'측정 관리'!$K$5:$K$204,"",0)}
A37: 30 | B37: @0xDepressionn | C37: P4 | D37: 57 | E37: B | F37: 403 | G37: 46100 | H37: 1 | I37: 949 | J37: 11.0084 | K37: 0.0116 | L37: 6 | M37: 1263 | N37: 16.5453 | O37: 0.0131 | P37: 39 | Q37: 3489 | R37: 26.5164 | S37: 0.0076 | T37: 0.075683297 | U37: -0.63800516 | W37: https://x.com/0xDepressionn | X37: WB-C030 | Y37: WB-K118 | Z37: {=_xlfn.XLOOKUP(X37,'측정 관리'!$A$5:$A$204,'측정 관리'!$K$5:$K$204,"",0)}
A38: 31 | B38: @woody_research | C38: P4 | D38: 3 | E38: D | F38: 6 | G38: 21200 | L38: 8 | M38: 1865 | N38: 22.753 | O38: 0.0122 | P38: 28 | Q38: 3431 | R38: 23.6739 | S38: 0.0069 | T38: 0.16183962 | U38: -0.4564267 | V38: 30일은 9/4 이후만 수집 | W38: https://x.com/woody_research | X38: WB-C031 | Y38: WB-K119 | Z38: {=_xlfn.XLOOKUP(X38,'측정 관리'!$A$5:$A$204,'측정 관리'!$K$5:$K$204,"",0)}
A39: 32 | B39: @zeuuss_01 | C39: P4 | D39: 65 | E39: B | F39: 524 | G39: 31000 | H39: 1 | I39: 1646 | J39: 16.9538 | K39: 0.0103 | L39: 19 | M39: 3725 | N39: 28.31 | O39: 0.0076 | P39: 74 | Q39: 5332 | R39: 21.328 | S39: 0.004 | T39: 0.172 | U39: -0.30138785 | W39: https://x.com/zeuuss_01 | X39: WB-C032 | Y39: WB-K117 | Z39: {=_xlfn.XLOOKUP(X39,'측정 관리'!$A$5:$A$204,'측정 관리'!$K$5:$K$204,"",0)}
A40: 33 | B40: @terra_gatsuki | C40: P4 | D40: 30 | E40: C | F40: 261 | G40: 25800 | L40: 6 | M40: 665 | N40: 4.8545 | O40: 0.0073 | P40: 9 | Q40: 714 | R40: 3.57 | S40: 0.005 | T40: 0.027674419 | U40: -0.068627451 | W40: https://x.com/terra_gatsuki | X40: WB-C033 | Y40: WB-K123 | Z40: {=_xlfn.XLOOKUP(X40,'측정 관리'!$A$5:$A$204,'측정 관리'!$K$5:$K$204,"",0)}
A41: 34 | B41: @plutos_eth | C41: P4 | D41: 24 | E41: C | F41: 192 | G41: 44400 | H41: 1 | I41: 1465 | J41: 1.0255 | K41: 0.0007 | L41: 3 | M41: 1478 | N41: 2.6604 | O41: 0.0018 | P41: 24 | Q41: 1608 | R41: 2.8944 | S41: 0.0018 | T41: 0.036216216 | U41: -0.080845771 | V41: AI 에이전트 콘텐츠 위주 · 반응 매우 낮음 | W41: https://x.com/plutos_eth | X41: WB-C034 | Y41: WB-K121 | Z41: {=_xlfn.XLOOKUP(X41,'측정 관리'!$A$5:$A$204,'측정 관리'!$K$5:$K$204,"",0)}
...

Sheet 글로벌 YT
A1: 글로벌 YouTube — 26개 채널 (롱폼)
A2: ■ 롱폼 영상 기준 (쇼츠 제외) · 퍼포먼스 = 30일 중앙 조회 P1 10,000+ · P2 3,000+ · P3 1,000+ · 비활동 = 30일 0개
A3: ■ YouTube는 공개 페이지에 좋아요 수가 없어 ER 대신 도달률(중앙 조회 ÷ 구독자)로 반응을 봄 · 조회수는 표시값(천 단위 반올림)
A4: ■ ⚠️ 영상 2개 이하 채널은 표본이 작아 등급 변동 큼 · @Gatzkiee 30일 평균은 바이럴 1건 영향 (중앙값 기준 권장)
G6: 24시간 | I6: 7일 | L6: 30일
A7: 순위 | B7: 채널 | C7: 핸들 | D7: 퍼포먼스 | E7: 구독자 | F7: 최근 영상 (일 전) | G7: 영상 | H7: 평균 조회 | I7: 영상 | J7: 평균 조회 | K7: 중앙 조회 | L7: 영상 | M7: 평균 조회 | N7: 중앙 조회 | O7: 도달률 (중앙÷구독) | P7: 메모 | Q7: 링크 | X7: 채널 ID | Y7: KOL ID | Z7: 측정 상태
A8: 1 | B8: gatzkiee | C8: @Gatzkiee | D8: P1 | E8: 35200 | F8: 2 | I8: 3 | J8: 12000 | K8: 12000 | L8: 12 | M8: 52358 | N8: 14000 | O8: 0.39772727 | Q8: https://www.youtube.com/@Gatzkiee | X8: WB-C044 | Y8: WB-K087 | Z8: {=_xlfn.XLOOKUP(X8,'측정 관리'!$A$5:$A$204,'측정 관리'!$K$5:$K$204,"",0)}
A9: 2 | B9: 100XClub | C9: @100xclub | D9: P1 | E9: 42500 | F9: 0 | G9: 1 | H9: 1300 | I9: 5 | J9: 10220 | K9: 11000 | L9: 18 | M9: 12339 | N9: 13000 | O9: 0.30588235 | Q9: https://www.youtube.com/@100xclub | X9: WB-C045 | Y9: WB-K088 | Z9: {=_xlfn.XLOOKUP(X9,'측정 관리'!$A$5:$A$204,'측정 관리'!$K$5:$K$204,"",0)}
A10: 3 | B10: Insane on Crypto | C10: @InsaneonCrypto | D10: P1 | E10: 21600 | F10: 4 | I10: 1 | J10: 10000 | K10: 10000 | L10: 2 | M10: 5600 | N10: 10000 | O10: 0.46296296 | Q10: https://www.youtube.com/@InsaneonCrypto | X10: WB-C046 | Y10: WB-K089 | Z10: {=_xlfn.XLOOKUP(X10,'측정 관리'!$A$5:$A$204,'측정 관리'!$K$5:$K$204,"",0)}
A11: 4 | B11: ItsRagnar | C11: @ItsRagnar | D11: P2 | E11: 35900 | F11: 2 | I11: 1 | J11: 3400 | K11: 3400 | L11: 5 | M11: 6820 | N11: 5600 | O11: 0.15598886 | Q11: https://www.youtube.com/@ItsRagnar | X11: WB-C047 | Y11: WB-K097 | Z11: {=_xlfn.XLOOKUP(X11,'측정 관리'!$A$5:$A$204,'측정 관리'!$K$5:$K$204,"",0)}
A12: 5 | B12: Philakone | C12: @philakonecrypto | D12: P2 | E12: 85700 | F12: 1 | G12: 1 | H12: 3500 | I12: 2 | J12: 4400 | K12: 5300 | L12: 3 | M12: 4967 | N12: 5300 | O12: 0.061843641 | Q12: https://www.youtube.com/@philakonecrypto | X12: WB-C048 | Y12: WB-K099 | Z12: {=_xlfn.XLOOKUP(X12,'측정 관리'!$A$5:$A$204,'측정 관리'!$K$5:$K$204,"",0)}
A13: 6 | B13: Koroush AK | C13: @Koroushak | D13: P3 | E13: 106000 | F13: 5 | I13: 1 | J13: 2400 | K13: 2400 | L13: 4 | M13: 2750 | N13: 2600 | O13: 0.024528302 | Q13: https://www.youtube.com/@Koroushak | X13: WB-C049 | Y13: WB-K109 | Z13: {=_xlfn.XLOOKUP(X13,'측정 관리'!$A$5:$A$204,'측정 관리'!$K$5:$K$204,"",0)}
A14: 7 | B14: MrCrypto PH | C14: @MrCryptoPH | D14: P3 | E14: 33600 | F14: 21 | L14: 2 | M14: 1350 | N14: 1600 | O14: 0.047619048 | Q14: https://www.youtube.com/@MrCryptoPH | X14: WB-C050 | Y14: WB-K110 | Z14: {=_xlfn.XLOOKUP(X14,'측정 관리'!$A$5:$A$204,'측정 관리'!$K$5:$K$204,"",0)}
A15: 8 | B15: DalarinTV - Crypto | C15: @DalarinTV | D15: P3 | E15: 41300 | F15: 0 | G15: 1 | H15: 867 | I15: 2 | J15: 2934 | K15: 5000 | L15: 6 | M15: 2074 | N15: 1500 | O15: 0.036319613 | Q15: https://www.youtube.com/@DalarinTV | X15: WB-C051 | Y15: WB-K111 | Z15: {=_xlfn.XLOOKUP(X15,'측정 관리'!$A$5:$A$204,'측정 관리'!$K$5:$K$204,"",0)}
A16: 9 | B16: Indep | C16: @Indep15 | D16: P3 | E16: 14500 | F16: 3 | I16: 3 | J16: 3241 | K16: 1400 | L16: 5 | M16: 2545 | N16: 1400 | O16: 0.096551724 | Q16: https://www.youtube.com/@Indep15 | X16: WB-C052 | Y16: WB-K112 | Z16: {=_xlfn.XLOOKUP(X16,'측정 관리'!$A$5:$A$204,'측정 관리'!$K$5:$K$204,"",0)}
A17: 10 | B17: Smithii | C17: @Smithii | D17: P3 | E17: 10400 | F17: 10 | L17: 2 | M17: 896 | N17: 1400 | O17: 0.13461538 | Q17: https://www.youtube.com/@Smithii | X17: WB-C053 | Y17: WB-K113 | Z17: {=_xlfn.XLOOKUP(X17,'측정 관리'!$A$5:$A$204,'측정 관리'!$K$5:$K$204,"",0)}
A18: 11 | B18: Nazza Crypto | C18: @nazzacrypto | D18: P3 | E18: 36300 | F18: 1 | G18: 1 | H18: 1700 | I18: 8 | J18: 2219 | K18: 1700 | L18: 13 | M18: 3348 | N18: 1200 | O18: 0.033057851 | Q18: https://www.youtube.com/@nazzacrypto | X18: WB-C054 | Y18: WB-K114 | Z18: {=_xlfn.XLOOKUP(X18,'측정 관리'!$A$5:$A$204,'측정 관리'!$K$5:$K$204,"",0)}
A19: 12 | B19: Follis | C19: @follis_ | D19: P3 | E19: 7210 | F19: 0 | G19: 1 | H19: 565 | I19: 3 | J19: 847 | K19: 775 | L19: 7 | M19: 1196 | N19: 1200 | O19: 0.16643551 | Q19: https://www.youtube.com/@follis_ | X19: WB-C055 | Y19: WB-K094 | Z19: {=_xlfn.XLOOKUP(X19,'측정 관리'!$A$5:$A$204,'측정 관리'!$K$5:$K$204,"",0)}
A20: 13 | B20: Buhok Gaming | C20: @BuhokGaming | D20: P4 | E20: 64400 | F20: 3 | I20: 3 | J20: 7767 | K20: 11000 | L20: 8 | M20: 3170 | N20: 746 | O20: 0.011583851 | Q20: https://www.youtube.com/@BuhokGaming | X20: WB-C056 | Y20: WB-K122 | Z20: {=_xlfn.XLOOKUP(X20,'측정 관리'!$A$5:$A$204,'측정 관리'!$K$5:$K$204,"",0)}
A21: 14 | B21: MURO CRYPTO | C21: c/murocrypto | D21: P4 | E21: 14300 | F21: 14 | L21: 4 | M21: 535 | N21: 667 | O21: 0.046643357 | Q21: https://www.youtube.com/c/murocrypto | X21: WB-C057 | Y21: WB-K093 | Z21: {=_xlfn.XLOOKUP(X21,'측정 관리'!$A$5:$A$204,'측정 관리'!$K$5:$K$204,"",0)}
A22: 15 | B22: Creative Crypto | C22: @CreativeCrypto | D22: P4 | E22: 17100 | F22: 10 | L22: 2 | M22: 417 | N22: 440 | O22: 0.025730994 | Q22: https://www.youtube.com/@CreativeCrypto | X22: WB-C058 | Y22: WB-K124 | Z22: {=_xlfn.XLOOKUP(X22,'측정 관리'!$A$5:$A$204,'측정 관리'!$K$5:$K$204,"",0)}
A23: 16 | B23: Whocares ML | C23: @whocaresml6684 | D23: 비활동 | E23: 474000 | F23: 195 | P23: 최근 롱폼 195일 전 | Q23: https://www.youtube.com/@whocaresml6684 | X23: WB-C059 | Y23: WB-K129 | Z23: {=_xlfn.XLOOKUP(X23,'측정 관리'!$A$5:$A$204,'측정 관리'!$K$5:$K$204,"",0)}
A24: 17 | B24: Rekt Capital | C24: @RektCapital | D24: 비활동 | E24: 114000 | F24: 45 | P24: 최근 롱폼 45일 전 | Q24: https://www.youtube.com/@RektCapital | X24: WB-C060 | Y24: WB-K090 | Z24: {=_xlfn.XLOOKUP(X24,'측정 관리'!$A$5:$A$204,'측정 관리'!$K$5:$K$204,"",0)}
A25: 18 | B25: OnlineBoss-Crypto | C25: @onlineboss-crypto | D25: 비활동 | E25: 69800 | F25: 165 | P25: 최근 롱폼 165일 전 | Q25: https://www.youtube.com/@onlineboss-crypto | X25: WB-C061 | Y25: WB-K127 | Z25: {=_xlfn.XLOOKUP(X25,'측정 관리'!$A$5:$A$204,'측정 관리'!$K$5:$K$204,"",0)}
A26: 19 | B26: TraderXO | C26: @TraderXO | D26: 비활동 | E26: 61200 | F26: 75 | P26: 최근 롱폼 75일 전 | Q26: https://www.youtube.com/@TraderXO | X26: WB-C062 | Y26: WB-K083 | Z26: {=_xlfn.XLOOKUP(X26,'측정 관리'!$A$5:$A$204,'측정 관리'!$K$5:$K$204,"",0)}
A27: 20 | B27: BossJapz Review | C27: @bossjapzreview | D27: 비활동 | E27: 58900 | F27: 225 | P27: 최근 롱폼 225일 전 | Q27: https://www.youtube.com/@bossjapzreview | X27: WB-C063 | Y27: WB-K130 | Z27: {=_xlfn.XLOOKUP(X27,'측정 관리'!$A$5:$A$204,'측정 관리'!$K$5:$K$204,"",0)}
A28: 21 | B28: CryptoEliz | C28: @CryptoEliz | D28: 비활동 | E28: 28100 | F28: 365 | P28: 최근 롱폼 365일 전 | Q28: https://www.youtube.com/@CryptoEliz | X28: WB-C064 | Y28: WB-K084 | Z28: {=_xlfn.XLOOKUP(X28,'측정 관리'!$A$5:$A$204,'측정 관리'!$K$5:$K$204,"",0)}
A29: 22 | B29: Cold Blooded Shiller | C29: @ColdBloodedShiller | D29: 비활동 | E29: 14900 | F29: 365 | P29: 최근 롱폼 365일 전 | Q29: https://www.youtube.com/@ColdBloodedShiller | X29: WB-C065 | Y29: WB-K092 | Z29: {=_xlfn.XLOOKUP(X29,'측정 관리'!$A$5:$A$204,'측정 관리'!$K$5:$K$204,"",0)}
A30: 23 | B30: Inmortal | C30: c/inmortalcrypto | D30: 비활동 | E30: 11800 | P30: 영상 없음 | Q30: https://www.youtube.com/c/inmortalcrypto | X30: WB-C066 | Y30: WB-K095 | Z30: {=_xlfn.XLOOKUP(X30,'측정 관리'!$A$5:$A$204,'측정 관리'!$K$5:$K$204,"",0)}
A31: 24 | B31: AltcoinSherpa | C31: c/Altcoinsherpa | D31: 비활동 | E31: 11600 | F31: 195 | P31: 최근 롱폼 195일 전 | Q31: https://www.youtube.com/c/Altcoinsherpa | X31: WB-C067 | Y31: WB-K104 | Z31: {=_xlfn.XLOOKUP(X31,'측정 관리'!$A$5:$A$204,'측정 관리'!$K$5:$K$204,"",0)}
A32: 25 | B32: Income Sharks | C32: @IncomeSharks | D32: 비활동 | E32: 8570 | F32: 285 | P32: 최근 롱폼 285일 전 | Q32: https://www.youtube.com/@IncomeSharks | X32: WB-C068 | Y32: WB-K082 | Z32: {=_xlfn.XLOOKUP(X32,'측정 관리'!$A$5:$A$204,'측정 관리'!$K$5:$K$204,"",0)}
A33: 26 | B33: Daan Crypto | C33: @daancrypto | D33: 비활동 | E33: 7150 | F33: 225 | P33: 최근 롱폼 225일 전 | Q33: https://www.youtube.com/@daancrypto | X33: WB-C069 | Y33: WB-K096 | Z33: {=_xlfn.XLOOKUP(X33,'측정 관리'!$A$5:$A$204,'측정 관리'!$K$5:$K$204,"",0)}

Sheet 글로벌 TG
A1: 글로벌 Telegram — 28개 채널
A2: ■ 퍼포먼스 = 30일 중앙 조회 P1 3,000+ · P2 1,500+ · P3 500+ · P4 500 미만 · 비활동 = 30일 3건 미만
A3: ■ TG 공개 채널은 반응 수가 없어 도달률(중앙 조회 ÷ 구독자)이 반응 지표 · 8%+면 구독자 참여가 살아있는 채널로 봄 [제안]
A4: ■ 비공개 4개는 웹 미리보기가 막혀 측정 불가
G6: 24시간 | I6: 7일 | L6: 30일
A7: 순위 | B7: 채널명 | C7: 채널 | D7: 퍼포먼스 | E7: 구독자 | F7: 마지막 글 | G7: 게시 | H7: 평균 조회 | I7: 게시 | J7: 평균 조회 | K7: 중앙 조회 | L7: 게시 | M7: 평균 조회 | N7: 중앙 조회 | O7: 도달률 | P7: 추세 (7d vs 30d) | Q7: 메모 | R7: 링크 | X7: 채널 ID | Y7: KOL ID | Z7: 측정 상태
A8: 1 | B8: cyclop | C8: cyclopalpha | D8: P2 | E8: 77200 | F8: 2026-09-25 | I8: 9 | J8: 2837 | K8: 2860 | L8: 9 | M8: 2837 | N8: 2860 | O8: 0.037046632 | P8: 0 | R8: https://t.me/cyclopalpha | X8: WB-C070 | Y8: WB-K100 | Z8: {=_xlfn.XLOOKUP(X8,'측정 관리'!$A$5:$A$204,'측정 관리'!$K$5:$K$204,"",0)}
A9: 2 | B9: Eric Cryptomans Journal | C9: Erics_Calls | D9: P2 | E9: 31300 | F9: 2026-09-25 | I9: 10 | J9: 4727 | K9: 2600 | L9: 105 | M9: 3058 | N9: 2710 | O9: 0.08658147 | P9: 0.54578156 | R9: https://t.me/Erics_Calls | X9: WB-C071 | Y9: WB-K101 | Z9: {=_xlfn.XLOOKUP(X9,'측정 관리'!$A$5:$A$204,'측정 관리'!$K$5:$K$204,"",0)}
A10: 3 | B10: Poseidon Kitchen | C10: poseidonkitchen | D10: P3 | E10: 11000 | F10: 2026-09-24 | I10: 15 | J10: 1128 | K10: 1070 | L10: 102 | M10: 1101 | N10: 1090 | O10: 0.099090909 | P10: 0.024523161 | R10: https://t.me/poseidonkitchen | X10: WB-C072 | Y10: WB-K085 | Z10: {=_xlfn.XLOOKUP(X10,'측정 관리'!$A$5:$A$204,'측정 관리'!$K$5:$K$204,"",0)}
A11: 4 | B11: winkle. | C11: w1nklerr | D11: P3 | E11: 7940 | F11: 2026-09-08 | L11: 4 | M11: 659 | N11: 675 | O11: 0.085012594 | R11: https://t.me/w1nklerr | X11: WB-C073 | Y11: WB-K115 | Z11: {=_xlfn.XLOOKUP(X11,'측정 관리'!$A$5:$A$204,'측정 관리'!$K$5:$K$204,"",0)}
A12: 5 | B12: Jaynecrypto | C12: jaynecrypto | D12: P4 | E12: 5210 | F12: 2026-09-27 | G12: 3 | H12: 238 | I12: 13 | J12: 381 | K12: 400 | L12: 100 | M12: 445 | N12: 451 | O12: 0.086564299 | P12: -0.14382022 | R12: https://t.me/jaynecrypto | X12: WB-C074 | Y12: WB-K107 | Z12: {=_xlfn.XLOOKUP(X12,'측정 관리'!$A$5:$A$204,'측정 관리'!$K$5:$K$204,"",0)}
A13: 6 | B13: 0xFrogify | C13: frogify0x | D13: P4 | E13: 8000 | F13: 2026-09-27 | G13: 1 | H13: 53 | I13: 6 | J13: 134 | K13: 162 | L13: 32 | M13: 177 | N13: 179 | O13: 0.022375 | P13: -0.24293785 | R13: https://t.me/frogify0x | X13: WB-C075 | Y13: WB-K125 | Z13: {=_xlfn.XLOOKUP(X13,'측정 관리'!$A$5:$A$204,'측정 관리'!$K$5:$K$204,"",0)}
A14: 7 | B14: Evan NICHE | C14: EvanNiche | D14: P4 | E14: 549 | F14: 2026-09-17 | L14: 3 | M14: 43 | N14: 41 | O14: 0.074681239 | R14: https://t.me/EvanNiche | X14: WB-C076 | Y14: WB-K108 | Z14: {=_xlfn.XLOOKUP(X14,'측정 관리'!$A$5:$A$204,'측정 관리'!$K$5:$K$204,"",0)}
A15: 8 | B15: DeFi Oracle - Gems | C15: DeFiOracleGems | D15: 비활동 | E15: 1810 | F15: 2026-09-09 | L15: 1 | M15: 1730 | N15: 1730 | O15: 0.9558011 | Q15: 마지막 글 2026-09-09 | R15: https://t.me/DeFiOracleGems | X15: WB-C077 | Y15: WB-K106 | Z15: {=_xlfn.XLOOKUP(X15,'측정 관리'!$A$5:$A$204,'측정 관리'!$K$5:$K$204,"",0)}
A16: 9 | B16: 0xchromium | C16: xchromium | D16: 비활동 | E16: 2480 | F16: 2026-09-16 | L16: 2 | M16: 138 | N16: 183 | O16: 0.073790323 | Q16: 마지막 글 2026-09-16 | R16: https://t.me/xchromium | X16: WB-C078 | Y16: WB-K120 | Z16: {=_xlfn.XLOOKUP(X16,'측정 관리'!$A$5:$A$204,'측정 관리'!$K$5:$K$204,"",0)}
A17: 10 | B17: Woody in crypto | C17: woody_research | D17: 비활동 | E17: 2010 | F17: 2026-09-16 | L17: 2 | M17: 125 | N17: 156 | O17: 0.07761194 | Q17: 마지막 글 2026-09-16 | R17: https://t.me/woody_research | X17: WB-C079 | Y17: WB-K119 | Z17: {=_xlfn.XLOOKUP(X17,'측정 관리'!$A$5:$A$204,'측정 관리'!$K$5:$K$204,"",0)}
A18: 11 | B18: Kepochnik Alpha | C18: kepochnikalpha | D18: 비활동 | E18: 7820 | F18: 2026-09-25 | I18: 1 | J18: 147 | K18: 147 | L18: 1 | M18: 147 | N18: 147 | O18: 0.018797954 | P18: 0 | Q18: 마지막 글 2026-09-25 | R18: https://t.me/kepochnikalpha | X18: WB-C080 | Y18: WB-K128 | Z18: {=_xlfn.XLOOKUP(X18,'측정 관리'!$A$5:$A$204,'측정 관리'!$K$5:$K$204,"",0)}
A19: 12 | B19: Nazza Crypto | C19: nazzacrypto | D19: 비활동 | E19: 156 | F19: 2026-09-23 | I19: 1 | J19: 24 | K19: 24 | L19: 2 | M19: 50 | N19: 76 | O19: 0.48717949 | P19: -0.52 | Q19: 마지막 글 2026-09-23 | R19: https://t.me/nazzacrypto | X19: WB-C081 | Y19: WB-K114 | Z19: {=_xlfn.XLOOKUP(X19,'측정 관리'!$A$5:$A$204,'측정 관리'!$K$5:$K$204,"",0)}
A20: 13 | B20: Klarck Alpha | C20: klarck_alpha | D20: 비활동 | E20: 36800 | F20: 2026-04-07 | Q20: 마지막 글 2026-04-07 | R20: https://t.me/klarck_alpha | X20: WB-C082 | Y20: WB-K102 | Z20: {=_xlfn.XLOOKUP(X20,'측정 관리'!$A$5:$A$204,'측정 관리'!$K$5:$K$204,"",0)}
A21: 14 | B21: Chad Crypto | C21: Chad_Crypto | D21: 비활동 | E21: 16000 | F21: 2026-07-30 | Q21: 마지막 글 2026-07-30 | R21: https://t.me/Chad_Crypto | X21: WB-C083 | Y21: WB-K116 | Z21: {=_xlfn.XLOOKUP(X21,'측정 관리'!$A$5:$A$204,'측정 관리'!$K$5:$K$204,"",0)}
A22: 15 | B22: Money Land | C22: deronin_alpha | D22: 비활동 | E22: 11600 | F22: 2026-08-11 | Q22: 마지막 글 2026-08-11 | R22: https://t.me/deronin_alpha | X22: WB-C084 | Y22: WB-K091 | Z22: {=_xlfn.XLOOKUP(X22,'측정 관리'!$A$5:$A$204,'측정 관리'!$K$5:$K$204,"",0)}
A23: 16 | B23: Plutos | C23: plutos_research | D23: 비활동 | E23: 9340 | F23: 2025-11-03 | Q23: 마지막 글 2025-11-03 | R23: https://t.me/plutos_research | X23: WB-C085 | Y23: WB-K121 | Z23: {=_xlfn.XLOOKUP(X23,'측정 관리'!$A$5:$A$204,'측정 관리'!$K$5:$K$204,"",0)}
A24: 17 | B24: Kitchen of Sully | C24: kitchenofsully | D24: 비활동 | E24: 8310 | F24: 2026-07-31 | Q24: 마지막 글 2026-07-31 | R24: https://t.me/kitchenofsully | X24: WB-C086 | Y24: WB-K105 | Z24: {=_xlfn.XLOOKUP(X24,'측정 관리'!$A$5:$A$204,'측정 관리'!$K$5:$K$204,"",0)}
A25: 18 | B25: Fried Dev | C25: FriedDev | D25: 비활동 | E25: 3940 | F25: 2026-07-10 | Q25: 마지막 글 2026-07-10 | R25: https://t.me/FriedDev | X25: WB-C087 | Y25: WB-K131 | Z25: {=_xlfn.XLOOKUP(X25,'측정 관리'!$A$5:$A$204,'측정 관리'!$K$5:$K$204,"",0)}
A26: 19 | B26: CryptoDarya | C26: Daryacrypto | D26: 비활동 | E26: 3870 | F26: 2025-06-25 | Q26: 마지막 글 2025-06-25 | R26: https://t.me/Daryacrypto | X26: WB-C088 | Y26: WB-K132 | Z26: {=_xlfn.XLOOKUP(X26,'측정 관리'!$A$5:$A$204,'측정 관리'!$K$5:$K$204,"",0)}
A27: 20 | B27: ZEU$ | C27: zeuusss_01 | D27: 비활동 | E27: 2450 | F27: 2026-07-08 | Q27: 마지막 글 2026-07-08 | R27: https://t.me/zeuusss_01 | X27: WB-C089 | Y27: WB-K117 | Z27: {=_xlfn.XLOOKUP(X27,'측정 관리'!$A$5:$A$204,'측정 관리'!$K$5:$K$204,"",0)}
A28: 21 | B28: 0xDepressionn | C28: xDepressionn | D28: 비활동 | E28: 2150 | F28: 2026-08-02 | Q28: 마지막 글 2026-08-02 | R28: https://t.me/xDepressionn | X28: WB-C090 | Y28: WB-K118 | Z28: {=_xlfn.XLOOKUP(X28,'측정 관리'!$A$5:$A$204,'측정 관리'!$K$5:$K$204,"",0)}
A29: 22 | B29: Gatsuki Trust Fund | C29: gatsuki_fund | D29: 비활동 | E29: 429 | F29: 2025-12-09 | Q29: 마지막 글 2025-12-09 | R29: https://t.me/gatsuki_fund | X29: WB-C091 | Y29: WB-K123 | Z29: {=_xlfn.XLOOKUP(X29,'측정 관리'!$A$5:$A$204,'측정 관리'!$K$5:$K$204,"",0)}
A30: 23 | B30: Trader HuB | C30: BullX192 | D30: 비활동 | E30: 175 | F30: 2025-10-11 | Q30: 마지막 글 2025-10-11 | R30: https://t.me/BullX192 | X30: WB-C092 | Y30: WB-K135 | Z30: {=_xlfn.XLOOKUP(X30,'측정 관리'!$A$5:$A$204,'측정 관리'!$K$5:$K$204,"",0)}
A31: 24 | B31: NoName gateway | C31: whalenoname | D31: 비활동 | E31: 73 | F31: 2025-09-26 | Q31: 마지막 글 2025-09-26 | R31: https://t.me/whalenoname | X31: WB-C093 | Y31: WB-K103 | Z31: {=_xlfn.XLOOKUP(X31,'측정 관리'!$A$5:$A$204,'측정 관리'!$K$5:$K$204,"",0)}
A32: 25 | B32: OfficialSabiigal | C32: OfficialSabiigal | D32: 미측정 | Q32: 웹 미리보기 비공개 (구독자·조회 확인 불가) | R32: https://t.me/OfficialSabiigal | X32: WB-C094 | Y32: WB-K086 | Z32: {=_xlfn.XLOOKUP(X32,'측정 관리'!$A$5:$A$204,'측정 관리'!$K$5:$K$204,"",0)}
A33: 26 | B33: certifiedchads | C33: certifiedchads | D33: 미측정 | Q33: 웹 미리보기 비공개 (구독자·조회 확인 불가) | R33: https://t.me/certifiedchads | X33: WB-C095 | Y33: WB-K126 | Z33: {=_xlfn.XLOOKUP(X33,'측정 관리'!$A$5:$A$204,'측정 관리'!$K$5:$K$204,"",0)}
A34: 27 | B34: halosden | C34: halosden | D34: 미측정 | Q34: 웹 미리보기 비공개 (구독자·조회 확인 불가) | R34: https://t.me/halosden | X34: WB-C096 | Y34: WB-K098 | Z34: {=_xlfn.XLOOKUP(X34,'측정 관리'!$A$5:$A$204,'측정 관리'!$K$5:$K$204,"",0)}
A35: 28 | B35: DeFiImmortal | C35: DeFiImmortal | D35: 미측정 | Q35: 웹 미리보기 비공개 (구독자·조회 확인 불가) | R35: https://t.me/DeFiImmortal | X35: WB-C097 | Y35: WB-K134 | Z35: {=_xlfn.XLOOKUP(X35,'측정 관리'!$A$5:$A$204,'측정 관리'!$K$5:$K$204,"",0)} -> 조회 불가

Sheet 한국 TG
A1: 한국 Telegram — 67개 채널
A2: ■ 퍼포먼스 = 30일 중앙 조회 P1 3,000+ · P2 1,500+ · P3 500+ · P4 500 미만 · 비활동 = 30일 3건 미만
A3: ■ TG 공개 채널은 반응 수가 없어 도달률(중앙 조회 ÷ 구독자)이 반응 지표 · 8%+면 구독자 참여가 살아있는 채널로 봄 [제안]
A4: ■ '8/25 시트 평균' = 원본 시트 기재값 (실측과 비교용)
G6: 24시간 | I6: 7일 | K6: 30일
A7: 순위 | B7: KOL | C7: 채널 | D7: 퍼포먼스 | E7: 구독자 | F7: 마지막 글 | G7: 게시 | H7: 평균 조회 | I7: 게시 | J7: 평균 조회 | K7: 게시 | L7: 평균 조회 | M7: 중앙 조회 | N7: 도달률 | O7: 추세 (7d vs 30d) | P7: 8/25 시트 평균 | Q7: 메모 | R7: 링크 | X7: 채널 ID | Y7: KOL ID | Z7: 측정 상태
A8: 1 | B8: CoinFluencer P2E&NFT | C8: hjwnews | D8: P1 | E8: 6630 | F8: 2026-09-17 | K8: 4 | L8: 2255 | M8: 3290 | N8: 0.49622926 | P8: 1942 | Q8: 저빈도 (마지막 9/17) | R8: https://t.me/hjwnews | X8: WB-C098 | Y8: WB-K002 | Z8: {=_xlfn.XLOOKUP(X8,'측정 관리'!$A$5:$A$204,'측정 관리'!$K$5:$K$204,"",0)}
A9: 2 | B9: 코인하는 해달 | C9: seaotterbtc | D9: P1 | E9: 30100 | F9: 2026-09-28 | G9: 4 | H9: 2623 | I9: 24 | J9: 5280 | K9: 133 | L9: 6033 | M9: 5000 | N9: 0.16611296 | O9: -0.12481353 | P9: 3947 | Q9: 한국 1위 | R9: https://t.me/seaotterbtc | X9: WB-C099 | Y9: WB-K001 | Z9: {=_xlfn.XLOOKUP(X9,'측정 관리'!$A$5:$A$204,'측정 관리'!$K$5:$K$204,"",0)}
A10: 3 | B10: 취미생활방 | C10: enjoymyhobby | D10: P1 | E10: 49700 | F10: 2026-09-28 | G10: 19 | H10: 1705 | I10: 93 | J10: 2728 | K10: 431 | L10: 3065 | M10: 3010 | N10: 0.06056338 | O10: -0.10995106 | P10: 3006 | Q10: 하루 14건 → 고정 필요 | R10: https://t.me/enjoymyhobby | X10: WB-C100 | Y10: WB-K003 | Z10: {=_xlfn.XLOOKUP(X10,'측정 관리'!$A$5:$A$204,'측정 관리'!$K$5:$K$204,"",0)}
A11: 4 | B11: jobless | C11: Jobless_investor | D11: P2 | E11: 6050 | F11: 2026-09-03 | K11: 6 | L11: 1540 | M11: 1750 | N11: 0.2892562 | P11: 589 | Q11: 저빈도 (마지막 9/3) | R11: https://t.me/Jobless_investor | X11: WB-C101 | Y11: WB-K011 | Z11: {=_xlfn.XLOOKUP(X11,'측정 관리'!$A$5:$A$204,'측정 관리'!$K$5:$K$204,"",0)}
A12: 5 | B12: 크립토마카세 | C12: cryptomacase | D12: P2 | E12: 11000 | F12: 2026-09-28 | G12: 2 | H12: 1604 | I12: 6 | J12: 1925 | K12: 25 | L12: 2052 | M12: 1830 | N12: 0.16636364 | O12: -0.061890838 | P12: 786 | Q12: 저빈도 · 고효율 | R12: https://t.me/cryptomacase | X12: WB-C102 | Y12: WB-K010 | Z12: {=_xlfn.XLOOKUP(X12,'측정 관리'!$A$5:$A$204,'측정 관리'!$K$5:$K$204,"",0)}
A13: 6 | B13: 라오니 | C13: Raoni1 | D13: P2 | E13: 14900 | F13: 2026-09-28 | G13: 11 | H13: 1035 | I13: 75 | J13: 1989 | K13: 329 | L13: 2293 | M13: 2200 | N13: 0.14765101 | O13: -0.13257741 | P13: 1050 | R13: https://t.me/Raoni1 | X13: WB-C103 | Y13: WB-K008 | Z13: {=_xlfn.XLOOKUP(X13,'측정 관리'!$A$5:$A$204,'측정 관리'!$K$5:$K$204,"",0)}
A14: 7 | B14: Crypto Judy | C14: lovejudylee | D14: P2 | E14: 17400 | F14: 2026-09-28 | G14: 23 | H14: 1873 | I14: 282 | J14: 2331 | K14: 839 | L14: 2416 | M14: 2210 | N14: 0.12701149 | O14: -0.035182119 | P14: 1085 | Q14: 하루 28건+ · 30일 일부만 수집 | R14: https://t.me/lovejudylee | X14: WB-C104 | Y14: WB-K007 | Z14: {=_xlfn.XLOOKUP(X14,'측정 관리'!$A$5:$A$204,'측정 관리'!$K$5:$K$204,"",0)} -> 일부 수집
A15: 8 | B15: 졸업준비위원회 | C15: officialunivercityofcrypto | D15: P2 | E15: 23000 | F15: 2026-09-28 | G15: 5 | H15: 1455 | I15: 35 | J15: 2824 | K15: 157 | L15: 3193 | M15: 2830 | N15: 0.12304348 | O15: -0.1155653 | P15: 1753 | R15: https://t.me/officialunivercityofcrypto | X15: WB-C105 | Y15: WB-K006 | Z15: {=_xlfn.XLOOKUP(X15,'측정 관리'!$A$5:$A$204,'측정 관리'!$K$5:$K$204,"",0)}
A16: 9 | B16: 킬베로스 | C16: killberosDAO | D16: P2 | E16: 15100 | F16: 2026-09-28 | G16: 4 | H16: 317 | I16: 14 | J16: 1034 | K16: 38 | L16: 1659 | M16: 1650 | N16: 0.10927152 | O16: -0.37673297 | P16: 2231 | Q16: 8/25 대비 하락 | R16: https://t.me/killberosDAO | X16: WB-C106 | Y16: WB-K014 | Z16: {=_xlfn.XLOOKUP(X16,'측정 관리'!$A$5:$A$204,'측정 관리'!$K$5:$K$204,"",0)}
A17: 10 | B17: 신기돈 | C17: tlsrltnf | D17: P2 | E17: 22900 | F17: 2026-09-28 | G17: 2 | H17: 756 | I17: 38 | J17: 1985 | K17: 137 | L17: 1972 | M17: 1840 | N17: 0.080349345 | O17: 0.0065922921 | P17: 755 | R17: https://t.me/tlsrltnf | X17: WB-C107 | Y17: WB-K009 | Z17: {=_xlfn.XLOOKUP(X17,'측정 관리'!$A$5:$A$204,'측정 관리'!$K$5:$K$204,"",0)}
A18: 11 | B18: 마샬 | C18: marshallog | D18: P2 | E18: 21700 | F18: 2026-09-28 | G18: 3 | H18: 446 | I18: 28 | J18: 1537 | K18: 154 | L18: 1848 | M18: 1730 | N18: 0.079723502 | O18: -0.16829004 | P18: 1244 | R18: https://t.me/marshallog | X18: WB-C108 | Y18: WB-K012 | Z18: {=_xlfn.XLOOKUP(X18,'측정 관리'!$A$5:$A$204,'측정 관리'!$K$5:$K$204,"",0)}
A19: 12 | B19: 잼민123 | C19: mujammin123 | D19: P2 | E19: 26200 | F19: 2026-09-28 | G19: 24 | H19: 1126 | I19: 135 | J19: 1557 | K19: 430 | L19: 1764 | M19: 1690 | N19: 0.064503817 | O19: -0.11734694 | P19: 1158 | R19: https://t.me/mujammin123 | X19: WB-C109 | Y19: WB-K013 | Z19: {=_xlfn.XLOOKUP(X19,'측정 관리'!$A$5:$A$204,'측정 관리'!$K$5:$K$204,"",0)}
A20: 13 | B20: A라는 사람 | C20: aispersons | D20: P3 | E20: 3920 | F20: 2026-09-27 | G20: 1 | H20: 195 | I20: 5 | J20: 378 | K20: 18 | L20: 654 | M20: 707 | N20: 0.18035714 | O20: -0.42201835 | P20: 1807 | Q20: 8/25 대비 하락 | R20: https://t.me/aispersons | X20: WB-C110 | Y20: WB-K029 | Z20: {=_xlfn.XLOOKUP(X20,'측정 관리'!$A$5:$A$204,'측정 관리'!$K$5:$K$204,"",0)}
A21: 14 | B21: Road To Rome | C21: HeadingtoRome | D21: P3 | E21: 4840 | F21: 2026-09-27 | G21: 1 | H21: 197 | I21: 2 | J21: 388 | K21: 6 | L21: 918 | M21: 718 | N21: 0.14834711 | O21: -0.57734205 | P21: 154 | R21: https://t.me/HeadingtoRome | X21: WB-C111 | Y21: WB-K028 | Z21: {=_xlfn.XLOOKUP(X21,'측정 관리'!$A$5:$A$204,'측정 관리'!$K$5:$K$204,"",0)}
A22: 15 | B22: Trader Hyun's channel | C22: TraderHyun | D22: P3 | E22: 6530 | F22: 2026-09-24 | I22: 2 | J22: 412 | K22: 14 | L22: 814 | M22: 880 | N22: 0.13476263 | O22: -0.49385749 | P22: 556 | R22: https://t.me/TraderHyun | X22: WB-C112 | Y22: WB-K023 | Z22: {=_xlfn.XLOOKUP(X22,'측정 관리'!$A$5:$A$204,'측정 관리'!$K$5:$K$204,"",0)}
A23: 16 | B23: T.A Crypto | C23: yul_papa | D23: P3 | E23: 8060 | F23: 2026-09-28 | G23: 16 | H23: 797 | I23: 51 | J23: 972 | K23: 256 | L23: 1033 | M23: 1010 | N23: 0.12531017 | O23: -0.059051307 | P23: 1658 | R23: https://t.me/yul_papa | X23: WB-C113 | Y23: WB-K019 | Z23: {=_xlfn.XLOOKUP(X23,'측정 관리'!$A$5:$A$204,'측정 관리'!$K$5:$K$204,"",0)}
A24: 17 | B24: 알파스쿨 | C24: AlphaSchool77 | D24: P3 | E24: 10800 | F24: 2026-09-27 | G24: 1 | H24: 776 | I24: 4 | J24: 965 | K24: 101 | L24: 1223 | M24: 1300 | N24: 0.12037037 | O24: -0.21095666 | P24: 506 | R24: https://t.me/AlphaSchool77 | X24: WB-C114 | Y24: WB-K018 | Z24: {=_xlfn.XLOOKUP(X24,'측정 관리'!$A$5:$A$204,'측정 관리'!$K$5:$K$204,"",0)}
A25: 18 | B25: 코인위키 | C25: CoinWiki_MMWW | D25: P3 | E25: 5910 | F25: 2026-09-28 | G25: 5 | H25: 477 | I25: 25 | J25: 556 | K25: 82 | L25: 626 | M25: 615 | N25: 0.10406091 | O25: -0.11182109 | P25: 423 | R25: https://t.me/CoinWiki_MMWW | X25: WB-C115 | Y25: WB-K033 | Z25: {=_xlfn.XLOOKUP(X25,'측정 관리'!$A$5:$A$204,'측정 관리'!$K$5:$K$204,"",0)}
A26: 19 | B26: 21M 포밍 | C26: vc_21m | D26: P3 | E26: 5540 | F26: 2026-09-22 | I26: 2 | J26: 411 | K26: 8 | L26: 556 | M26: 567 | N26: 0.10234657 | O26: -0.26079137 | P26: 2093 | Q26: 8/25 대비 하락 | R26: https://t.me/vc_21m | X26: WB-C116 | Y26: WB-K034 | Z26: {=_xlfn.XLOOKUP(X26,'측정 관리'!$A$5:$A$204,'측정 관리'!$K$5:$K$204,"",0)}
A27: 20 | B27: 바나나우유 일기장 | C27: Bananamilkrich | D27: P3 | E27: 8760 | F27: 2026-09-24 | I27: 1 | J27: 323 | K27: 10 | L27: 928 | M27: 892 | N27: 0.10182648 | O27: -0.65193966 | P27: 985 | R27: https://t.me/Bananamilkrich | X27: WB-C117 | Y27: WB-K022 | Z27: {=_xlfn.XLOOKUP(X27,'측정 관리'!$A$5:$A$204,'측정 관리'!$K$5:$K$204,"",0)}
A28: 21 | B28: 크립토폴유 | C28: cryptoforu12 | D28: P3 | E28: 7620 | F28: 2026-09-27 | G28: 2 | H28: 601 | I28: 10 | J28: 999 | K28: 35 | L28: 962 | M28: 766 | N28: 0.10052493 | O28: 0.038461538 | P28: 573 | R28: https://t.me/cryptoforu12 | X28: WB-C118 | Y28: WB-K027 | Z28: {=_xlfn.XLOOKUP(X28,'측정 관리'!$A$5:$A$204,'측정 관리'!$K$5:$K$204,"",0)}
A29: 22 | B29: 개인적인 DYOR | C29: LEEHEESANGDYOR | D29: P3 | E29: 9730 | F29: 2026-09-28 | G29: 1 | H29: 403 | I29: 17 | J29: 899 | K29: 67 | L29: 1251 | M29: 976 | N29: 0.10030832 | O29: -0.2813749 | P29: 726 | R29: https://t.me/LEEHEESANGDYOR | X29: WB-C119 | Y29: WB-K021 | Z29: {=_xlfn.XLOOKUP(X29,'측정 관리'!$A$5:$A$204,'측정 관리'!$K$5:$K$204,"",0)}
A30: 23 | B30: BMT | C30: BMTube | D30: P3 | E30: 13700 | F30: 2026-09-28 | G30: 4 | H30: 629 | I30: 39 | J30: 1869 | K30: 84 | L30: 1622 | M30: 1200 | N30: 0.087591241 | O30: 0.15228113 | P30: 1248 | R30: https://t.me/BMTube | X30: WB-C120 | Y30: WB-K020 | Z30: {=_xlfn.XLOOKUP(X30,'측정 관리'!$A$5:$A$204,'측정 관리'!$K$5:$K$204,"",0)}
A31: 24 | B31: BQ 비큐 | C31: BQTelegram | D31: P3 | E31: 9600 | F31: 2026-09-27 | G31: 1 | H31: 281 | I31: 12 | J31: 519 | K31: 98 | L31: 1000 | M31: 821 | N31: 0.085520833 | O31: -0.481 | P31: 487 | R31: https://t.me/BQTelegram | X31: WB-C121 | Y31: WB-K025 | Z31: {=_xlfn.XLOOKUP(X31,'측정 관리'!$A$5:$A$204,'측정 관리'!$K$5:$K$204,"",0)}
A32: 25 | B32: 나백이의코인라이프 | C32: ysytop2 | D32: P3 | E32: 9360 | F32: 2026-09-27 | G32: 5 | H32: 701 | I32: 51 | J32: 954 | K32: 305 | L32: 891 | M32: 720 | N32: 0.076923077 | O32: 0.070707071 | P32: 366 | R32: https://t.me/ysytop2 | X32: WB-C122 | Y32: WB-K015 | Z32: {=_xlfn.XLOOKUP(X32,'측정 관리'!$A$5:$A$204,'측정 관리'!$K$5:$K$204,"",0)}
A33: 26 | B33: 코백남 | C33: cobacknamannounce | D33: P3 | E33: 18000 | F33: 2026-09-28 | G33: 12 | H33: 534 | I33: 78 | J33: 1168 | K33: 270 | L33: 1424 | M33: 1300 | N33: 0.072222222 | O33: -0.17977528 | P33: 465 | Q33: 시트 팔로워는 TG+YT 합산으로 보임 | R33: https://t.me/cobacknamannounce | X33: WB-C123 | Y33: WB-K005 | Z33: {=_xlfn.XLOOKUP(X33,'측정 관리'!$A$5:$A$204,'측정 관리'!$K$5:$K$204,"",0)}
A34: 27 | B34: 큐브의 유기농 크립토 쌀농장 | C34: cubestudy1557 | D34: P3 | E34: 9320 | F34: 2026-09-27 | I34: 12 | J34: 498 | K34: 38 | L34: 668 | M34: 624 | N34: 0.06695279 | O34: -0.25449102 | P34: 414 | R34: https://t.me/cubestudy1557 | X34: WB-C124 | Y34: WB-K031 | Z34: {=_xlfn.XLOOKUP(X34,'측정 관리'!$A$5:$A$204,'측정 관리'!$K$5:$K$204,"",0)}
A35: 28 | B35: 코인소년 | C35: coinboys | D35: P3 | E35: 15600 | F35: 2026-09-28 | G35: 15 | H35: 1006 | I35: 163 | J35: 1079 | K35: 616 | L35: 1197 | M35: 1030 | N35: 0.066025641 | O35: -0.098579783 | P35: 796 | Q35: 시트 팔로워는 TG+YT 합산으로 보임 | R35: https://t.me/coinboys | X35: WB-C125 | Y35: WB-K016 | Z35: {=_xlfn.XLOOKUP(X35,'측정 관리'!$A$5:$A$204,'측정 관리'!$K$5:$K$204,"",0)}
A36: 29 | B36: 요블이네 | C36: yobeullyANN | D36: P3 | E36: 22700 | F36: 2026-09-28 | G36: 12 | H36: 694 | I36: 45 | J36: 1294 | K36: 185 | L36: 1670 | M36: 1480 | N36: 0.065198238 | O36: -0.2251497 | P36: 851 | R36: https://t.me/yobeullyANN | X36: WB-C126 | Y36: WB-K017 | Z36: {=_xlfn.XLOOKUP(X36,'측정 관리'!$A$5:$A$204,'측정 관리'!$K$5:$K$204,"",0)}
A37: 30 | B37: 꿀찾는 양말 | C37: Honeyofwhitesocks_2 | D37: P3 | E37: 11400 | F37: 2026-09-28 | G37: 8 | H37: 386 | I37: 169 | J37: 642 | K37: 460 | L37: 683 | M37: 628 | N37: 0.055087719 | O37: -0.060029283 | P37: 312 | R37: https://t.me/Honeyofwhitesocks_2 | X37: WB-C127 | Y37: WB-K030 | Z37: {=_xlfn.XLOOKUP(X37,'측정 관리'!$A$5:$A$204,'측정 관리'!$K$5:$K$204,"",0)}
A38: 31 | B38: 젠티 | C38: Jenti_DeFi | D38: P3 | E38: 14400 | F38: 2026-09-27 | G38: 3 | H38: 446 | I38: 20 | J38: 586 | K38: 94 | L38: 732 | M38: 772 | N38: 0.053611111 | O38: -0.19945355 | P38: 856 | R38: https://t.me/Jenti_DeFi | X38: WB-C128 | Y38: WB-K026 | Z38: {=_xlfn.XLOOKUP(X38,'측정 관리'!$A$5:$A$204,'측정 관리'!$K$5:$K$204,"",0)}
A39: 32 | B39: 크립토스쿨 다오 | C39: CRYPTOSCH00L | D39: P3 | E39: 12600 | F39: 2026-09-28 | G39: 4 | H39: 229 | I39: 44 | J39: 459 | K39: 191 | L39: 530 | M39: 528 | N39: 0.041904762 | O39: -0.13396226 | P39: 265 | R39: https://t.me/CRYPTOSCH00L | X39: WB-C129 | Y39: WB-K035 | Z39: {=_xlfn.XLOOKUP(X39,'측정 관리'!$A$5:$A$204,'측정 관리'!$K$5:$K$204,"",0)}
A40: 33 | B40: 에어드랍코리아 | C40: airdrop_kor | D40: P3 | E40: 21900 | F40: 2026-09-28 | G40: 5 | H40: 360 | I40: 28 | J40: 779 | K40: 131 | L40: 959 | M40: 844 | N40: 0.038538813 | O40: -0.18769552 | P40: 756 | Q40: 에어드랍 키워드 | R40: https://t.me/airdrop_kor | X40: WB-C130 | Y40: WB-K024 | Z40: {=_xlfn.XLOOKUP(X40,'측정 관리'!$A$5:$A$204,'측정 관리'!$K$5:$K$204,"",0)}
A41: 34 | B41: 코인맵핵 | C41: centurywhale | D41: P3 | E41: 16700 | F41: 2026-09-28 | G41: 8 | H41: 221 | I41: 32 | J41: 451 | K41: 76 | L41: 625 | M41: 617 | N41: 0.036946108 | O41: -0.2784 | P41: 617 | R41: https://t.me/centurywhale | X41: WB-C131 | Y41: WB-K032 | Z41: {=_xlfn.XLOOKUP(X41,'측정 관리'!$A$5:$A$204,'측정 관리'!$K$5:$K$204,"",0)}
...

Sheet 한국 YT
A1: 한국 YouTube — 23개 채널 (롱폼)
A2: ■ 퍼포먼스 = 30일 롱폼 중앙 조회 P1 10,000+ · P2 3,000+ · P3 1,000+ · 비활동 = 30일 0개
A3: ■ 한국 YT는 24시간 단위 수집을 하지 않아 '최근 영상'(경과일)으로 대체 · 쇼츠는 별도 칸 (최근 N개 평균)
A4: ■ 30일 안에 롱폼을 올린 채널은 23곳 중 소수 — 한국은 TG 중심으로 볼 것
G6: 7일 | I6: 30일
A7: 순위 | B7: KOL | C7: 채널 | D7: 퍼포먼스 | E7: 구독자 | F7: 최근 영상 | G7: 영상 | H7: 평균 조회 | I7: 영상 | J7: 평균 조회 | K7: 중앙 조회 | L7: 도달률 | M7: 쇼츠 평균 (최근 N개) | N7: 메모 | O7: 링크 | X7: 채널 ID | Y7: KOL ID | Z7: 측정 상태
A8: 1 | B8: 매실남 | C8: @pluman | D8: P2 | E8: 10200 | F8: 3일 전 | G8: 2 | H8: 3800 | I8: 3 | J8: 5867 | K8: 6200 | L8: 0.60784314 | O8: https://www.youtube.com/@pluman | X8: WB-C165 | Y8: WB-K004 | Z8: {=_xlfn.XLOOKUP(X8,'측정 관리'!$A$5:$A$204,'측정 관리'!$K$5:$K$204,"",0)}
A9: 2 | B9: 코백남 | C9: @cobacknam | D9: P2 | E9: 57900 | F9: 14일 전 | I9: 1 | J9: 4300 | K9: 4300 | L9: 0.074265976 | M9: 2,595 (10개) | N9: TG 채널 병행 | O9: https://www.youtube.com/@cobacknam | X9: WB-C166 | Y9: WB-K005 | Z9: {=_xlfn.XLOOKUP(X9,'측정 관리'!$A$5:$A$204,'측정 관리'!$K$5:$K$204,"",0)}
A10: 3 | B10: coinfluencer | C10: @CoinFluencer | D10: P2 | E10: 99300 | F10: 4일 전 | G10: 1 | H10: 2200 | I10: 2 | J10: 2750 | K10: 3300 | L10: 0.033232628 | M10: 2,395 (4개) | N10: TG hjwnews 병행 | O10: https://www.youtube.com/@CoinFluencer | X10: WB-C167 | Y10: WB-K002 | Z10: {=_xlfn.XLOOKUP(X10,'측정 관리'!$A$5:$A$204,'측정 관리'!$K$5:$K$204,"",0)}
A11: 4 | B11: 나백이 | C11: @naback222 | D11: P3 | E11: 16700 | F11: 21일 전 | I11: 1 | J11: 2900 | K11: 2900 | L11: 0.17365269 | O11: https://www.youtube.com/@naback222 | X11: WB-C168 | Y11: WB-K015 | Z11: {=_xlfn.XLOOKUP(X11,'측정 관리'!$A$5:$A$204,'측정 관리'!$K$5:$K$204,"",0)}
A12: 5 | B12: 코인소년 | C12: @coinboys | D12: P3 | E12: 53200 | F12: 2일 전 | G12: 2 | H12: 2350 | I12: 6 | J12: 2333 | K12: 2200 | L12: 0.041353383 | M12: 2,800 (9개) | N12: TG 채널 병행 | O12: https://www.youtube.com/@coinboys | X12: WB-C169 | Y12: WB-K016 | Z12: {=_xlfn.XLOOKUP(X12,'측정 관리'!$A$5:$A$204,'측정 관리'!$K$5:$K$204,"",0)}
A13: 6 | B13: T.A Crypto | C13: @TA_crypto | D13: P3 | E13: 7410 | F13: 10일 전 | I13: 1 | J13: 1200 | K13: 1200 | L13: 0.16194332 | M13: 1,142 (10개) | N13: TG 채널 병행 | O13: https://www.youtube.com/@TA_crypto | X13: WB-C170 | Y13: WB-K019 | Z13: {=_xlfn.XLOOKUP(X13,'측정 관리'!$A$5:$A$204,'측정 관리'!$K$5:$K$204,"",0)}
A14: 7 | B14: 크립토메이지 | C14: @cryptocurrencymage | D14: P4 | E14: 8590 | F14: 1일 전 | G14: 3 | H14: 711 | I14: 3 | J14: 711 | K14: 570 | L14: 0.066356228 | O14: https://www.youtube.com/@cryptocurrencymage | X14: WB-C171 | Y14: WB-K037 | Z14: {=_xlfn.XLOOKUP(X14,'측정 관리'!$A$5:$A$204,'측정 관리'!$K$5:$K$204,"",0)}
A15: 8 | B15: 에어드랍 ATM | C15: @airdropatm | D15: P4 | E15: 10000 | F15: 10일 전 | I15: 1 | J15: 476 | K15: 476 | L15: 0.0476 | M15: 조회 실패 | O15: https://www.youtube.com/@airdropatm | X15: WB-C172 | Y15: WB-K038 | Z15: {=_xlfn.XLOOKUP(X15,'측정 관리'!$A$5:$A$204,'측정 관리'!$K$5:$K$204,"",0)}
A16: 9 | B16: 돈버는 꿀정보 | C16: @donkkul | D16: 비활동 | E16: 9640 | F16: 약 2년 전 | M16: 28,983 (6개, 27,000 1건 포함) | N16: 롱폼 중단 | O16: https://www.youtube.com/@donkkul | X16: WB-C173 | Y16: WB-K071 | Z16: {=_xlfn.XLOOKUP(X16,'측정 관리'!$A$5:$A$204,'측정 관리'!$K$5:$K$204,"",0)}
A17: 10 | B17: 잼민123 | C17: @jammin2 | D17: 비활동 | E17: 25300 | F17: 105일 전 | M17: 5,800 (1개) | N17: 롱폼 중단 | O17: https://www.youtube.com/@jammin2 | X17: WB-C174 | Y17: WB-K013 | Z17: {=_xlfn.XLOOKUP(X17,'측정 관리'!$A$5:$A$204,'측정 관리'!$K$5:$K$204,"",0)}
A18: 11 | B18: 영투한 | C18: @02HAN | D18: 비활동 | E18: 10700 | F18: 45일 전 | M18: 4,600 (1개) | N18: 롱폼 중단 | O18: https://www.youtube.com/@02HAN | X18: WB-C175 | Y18: WB-K069 | Z18: {=_xlfn.XLOOKUP(X18,'측정 관리'!$A$5:$A$204,'측정 관리'!$K$5:$K$204,"",0)}
A19: 12 | B19: 왕베이 | C19: @Wangbei__ | D19: 비활동 | E19: 3140 | F19: 75일 전 | M19: 1,920 (5개) | N19: 롱폼 중단 | O19: https://www.youtube.com/@Wangbei__ | X19: WB-C176 | Y19: WB-K044 | Z19: {=_xlfn.XLOOKUP(X19,'측정 관리'!$A$5:$A$204,'측정 관리'!$K$5:$K$204,"",0)}
